Workbook

Sheet ROSTER
B1: ROSTER SQ1 | C1: HL8082 | D1: 31CC | AJ1: A872
C2: A862 | D2: A02
C3: A869 | F3: ENGCHG | AJ3: A879
B4: 5 | C4: A864 | I4: A10+OOP | AJ4: A864
B5: 2026 | C5: A863 | K5: A11 | AJ5: A879
C6: A873 | P6: A06+OOP | AJ6: A870
B7: HCM BASE MAINTENANCE CENTER | C7: A867 | M7: A08+OOP | AJ7: A866
C8: A871 | Y8: A01 | AJ8: A869
C9: A868 | X9: A02 | AI9: A869 | AJ9: A879
C10: A861 | Y10: A12+OOP+LDG+ENGCHG
C11: A872 | AE11: ENGCHG | AJ11: A397
C12: A615 | T12: EA17
C13: A507 | Y13: EA22
C14: A396 | Z14: EA20
C15: A877 | T15: ENG CHG
N17: AMOS ETL | O17: AMOS ETL | P17: SECT 4 | Q17: SECT 4 | AE17: SECT 4 | AF17: SECT 4
N18: ATVSLD | O18: ATVSLD | P18: AMOS ETL | Q18: AMOS ETL | R18: AMOS ETL | S18: AMOS ETL | Y18: ATHK | Z18: DIFF A321 | AA18: DIFF A321 | AB18: DIFF A321 | AC18: DIFF A321 | AD18: DIFF A321 | AE18: DIFF A321 | AF18: DIFF A321 | AG18: DIFF A321 | AH18: DIFF A321
N19: DIFF A321 | O19: DIFF A321 | P19: DIFF A321 | Q19: DIFF A321 | R19: DIFF A321 | S19: DIFF A321 | T19: DIFF A321 | U19: DIFF A321 | V19: DIFF A321 | W19: DIFF A321 | X19: DIFF A321 | Y19: EWIS | Z19: EWIS | AA19: EWIS | AB19: EWIS | AC19: EWIS | AD19: EWIS | AE19: EWIS
N20: PRAC 787 | O20: PRAC 787 | P20: PRAC 787 | Q20: PRAC 787 | R20: PRAC 787 | S20: PRAC 787 | T20: PRAC 787 | U20: PRAC 787 | V20: PRAC 787 | W20: PRAC 787 | X20: PRAC 787 | Y20: PRAC 787 | Z20: PRAC 787 | AA20: PRAC 787 | AB20: PRAC 787 | AC20: PRAC 787 | AD20: PRAC 787 | AE20: PRAC 787 2 | AF20: PRAC 787 2 | AG20: PRAC 787 2 | AH20: PRAC 787 2
G21: GD | I21: ATHK | K21: ATHK | L21: ATVSLD | N21: ATHK | P21: HF | Q21: ATVSLD | U21: ATVSLD | W21: ATVSLD | AB21: ATVSLD | AC21: ATVSLD | AF21: ATVSLD | AG21: ATVSLD
D22: CPH | H22: PUS | I22: PUS | K22: PUS/CPH | M22: PUS | N22: PUS | P22: PUS | Q22: PUS | R22: PUS | S22: PUS | U22: PUS | Y22: CPH | Z22: PUS | AC22: PUS | AE22: PUS | AF22: PUS | AG22: PUS | AH22: PUS
D23: =IFERROR(IF(WEEKDAY(D24)=1,"CN","T"&WEEKDAY(D24)),"") -> T6 | E23: =IFERROR(IF(WEEKDAY(E24)=1,"CN","T"&WEEKDAY(E24)),"") -> T7 | F23: =IFERROR(IF(WEEKDAY(F24)=1,"CN","T"&WEEKDAY(F24)),"") -> CN | G23: =IFERROR(IF(WEEKDAY(G24)=1,"CN","T"&WEEKDAY(G24)),"") -> T2 | H23: =IFERROR(IF(WEEKDAY(H24)=1,"CN","T"&WEEKDAY(H24)),"") -> T3 | I23: =IFERROR(IF(WEEKDAY(I24)=1,"CN","T"&WEEKDAY(I24)),"") -> T4 | J23: =IFERROR(IF(WEEKDAY(J24)=1,"CN","T"&WEEKDAY(J24)),"") -> T5 | K23: =IFERROR(IF(WEEKDAY(K24)=1,"CN","T"&WEEKDAY(K24)),"") -> T6 | ... AI23: =IFERROR(IF(WEEKDAY(AI24)=1,"CN","T"&WEEKDAY(AI24)),"") -> T2 | AJ23: Ngày Công | AK23: Chứng Chỉ | AL23: Số ĐT
A24: STT | B24: HỌ VÀ TÊN | C24: MÃ VAECO | D24: =DATE($B$5,$B$4,1) -> 46143 | E24: =D24+1 -> 46144 | F24: =E24+1 -> 46145 | G24: =F24+1 -> 46146 | H24: =G24+1 -> 46147 | I24: =H24+1 -> 46148 | J24: =I24+1 -> 46149 | K24: =J24+1 -> 46150 | L24: =K24+1 -> 46151 | ... AI24: =AH24+1 -> 46174 | AM24: Đào tạo/P/N | AN24: Số CC | AO24: Lấy WS 2024 | AP24: Vệ Sinh
A25: 1 | B25: Phạm Tấn Độ | C25: VAE02582 | D25: N/A | E25: N/A | F25: N/A | G25: N/A | H25: N/A | I25: N/A | J25: N/A | K25: N/A | L25: N/A | M25: N/A | N25: N/A | O25: N/A | P25: N/A | Q25: N/A | R25: N/A | S25: N/A | T25: N/A | U25: N/A | V25: N/A | W25: N/A | X25: N/A | Y25: N/A | Z25: N/A | AA25: N/A | AB25: ATVSLD | AC25: N/A | AD25: NVSP ZOOM | AE25: N/A | AF25: N/A | AG25: N/A | AH25: N/A | AI25: N/A | AJ25: =COUNTIFS(D25:AG25,"<>"&"?",D25:AG25,"<>"&"",D25:AG25,"<>"&"fe",D25:AG25,"<>"&"vn") -> 30 | AK25: B1 B787/A321 | AL25: 0765060613 | AN25: 482 AC
A26: 2 | B26: Nguyễn Đình Hiệt | C26: VAE00750 | D26: N | E26: N | F26: TD | G26: TD | H26: TD | I26: N | J26: TD | K26: TD | L26: TD | M26: N | N26: TD | O26: TD | P26: TD | Q26: TD | R26: TD | S26: N | T26: N | U26: TD | V26: TD | W26: TD | X26: TD | Y26: TD | Z26: TD | AA26: TD | AJ26: =COUNTIFS(D26:AG26,"<>"&"?",D26:AG26,"<>"&"",D26:AG26,"<>"&"fe",D26:AG26,"<>"&"vn") -> 18 | AK26: B2 B787/A321 | AL26: 0908206182 | AN26: 421 AC
A27: 1 | B27: Trần Hoàng Nhung | C27: VAE02591 | D27: HL8082-PPC | E27: HL8082-PPC | F27: HL8082-PPC | G27: HL8082-PPC | H27: HL8082-PPC | I27: A864-PPC | J27: N | K27: N | L27: N | M27: A867-PPC | N27: HOC ETL | O27: HOC ETL | P27: A873-PPC | Q27: A873-PPC | R27: A873-PPC | S27: A873-PPC | T27: N | U27: A877-PPC | V27: A877-PPC | W27: N | X27: A868-PPC | Y27: A861-PPC | Z27: A861-PPC | AA27: N | AB27: ATVSLD | AC27: AMOS OL | AD27: AMOS OL | AE27: AMOS OL | AF27: N | AG27: N | AH27: N | AJ27: =COUNTIFS(D27:AG27,"<>"&"?",D27:AG27,"<>"&"",D27:AG27,"<>"&"fe",D27:AG27,"<>"&"vn") -> 22 | AK27: PPC/EA787 | AL27: 0906852989 | AM27: NGHỈ 7,8,9,29,31/5
A28: 2 | B28: Lê Thanh Hải | C28: VAE02718 | D28: HL8082-34567 | E28: A869-FM | F28: HL8082-ALL | G28: N | H28: HL8082-ALL | I28: A864-FM | J28: A864-FM | K28: A863-FM | L28: N | M28: A867-FM | N28: A867-FM | O28: A867-FM | P28: A873-FM | Q28: N | R28: A873-FM | S28: A873-FM | T28: A615-FM | U28: N | V28: N | W28: P | X28: P | Y28: P | Z28: P | AA28: P | AB28: P | AC28: P | AJ28: =COUNTIFS(D28:AG28,"<>"&"?",D28:AG28,"<>"&"",D28:AG28,"<>"&"fe",D28:AG28,"<>"&"vn") -> 14 | AK28: B1 B787/A321 | AL28: 0979690783 | AN28: 489 AC | AR28: 0
A29: 3 | B29: Nguyễn Thành Vũ | C29: VAE02589 | D29: TD | E29: TD | F29: N | G29: TD | H29: TD | I29: TD | J29: TD | K29: TD | L29: TD | M29: TD | N29: N | O29: TD | P29: TD | Q29: FM | R29: TD | S29: TD | T29: TD | U29: N | V29: A877-FM | W29: N | X29: TD | Y29: TD | Z29: TD | AA29: N | AB29: TD | AC29: ATVSLD | AD29: TD | AE29: TD | AF29: TD | AG29: TD | AH29: N | AJ29: =COUNTIFS(D29:AG29,"<>"&"?",D29:AG29,"<>"&"",D29:AG29,"<>"&"fe",D29:AG29,"<>"&"vn") -> 25 | AK29: B1 B787/A321 | AL29: 0973339492 | AN29: 481 AC | AR29: 0
A30: 54 | B30: Nguyễn Đức Tuân | C30: VAE00732 | D30: HL8082-128 | E30: HL8082-ALL | F30: N | G30: HL8082-ALL | H30: HL8082-ALL | I30: HL8082-ALL | J30: N | K30: A863-34 | L30: A863-34567 | M30: A867-34567 | N30: A867-34567 | O30: A867-34567 | P30: HF | Q30: AMOS ETL | R30: Đ2 | S30: N | T30: N | U30: A877-ENG | V30: A877-ENG | W30: A877-FM | X30: N | Y30: A861- | Z30: N | AI30: FE | AJ30: =COUNTIFS(D30:AG30,"<>"&"?",D30:AG30,"<>"&"",D30:AG30,"<>"&"fe",D30:AG30,"<>"&"vn") -> 17 | AK30: B1 B787/ATR/A321 | AL30: 0979747380 | AN30: 569 AC | AR30: 0
A31: 4 | B31: Đào Việt Hải | C31: VAE00708 | D31: HL8082-34567 | E31: N | F31: A869-EC | G31: A869-EC@16H | H31: N | I31: A864-34567 | J31: A864-34567 | K31: A863-128@14H | L31: N | M31: A867-34567 | N31: A867-34567 | O31: A867-34567 | P31: N | Q31: W/O ENG | R31: W/O ENG | S31: W/O ENG | T31: N | U31: A877-ENG@16H | V31: A877-ENG@16H | W31: N | X31: A868-128 | Y31: ATHK | AB31: ATHK | AJ31: =COUNTIFS(D31:AG31,"<>"&"?",D31:AG31,"<>"&"",D31:AG31,"<>"&"fe",D31:AG31,"<>"&"vn") -> 17 | AK31: B1 787 | AL31: 0908630644 | AN31: 425 AC | AR31: 0
A32: 5 | B32: Phạm Ngọc Anh | C32: VAE01348 | D32: A862-34567 | E32: A869-EC | F32: N | G32: A869-EC | H32: A869-EC | I32: N | J32: A864-128 | K32: A863-34 | L32: A863-ALL@14H | M32: N | N32: A867-128 | O32: A867-128 | P32: A873-34 | Q32: N | R32: A873-34567 | S32: A873-ALL | T32: A877-ENG | U32: A877-ENG | V32: N | W32: A877-ENG | X32: N | Y32: A861- | AB32: ATVSLD | AJ32: =COUNTIFS(D32:AG32,"<>"&"?",D32:AG32,"<>"&"",D32:AG32,"<>"&"fe",D32:AG32,"<>"&"vn") -> 17 | AK32: B1 787 | AL32: 0902153933 | AN32: 460 AC | AR32: 0
A33: 6 | B33: Hứa Quang Trung | C33: VAE02481 | D33: A862-FM | E33: N | F33: N | G33: A869-FM | H33: A869-FM | I33: A864-34567 | J33: A864-34567 | K33: N | L33: A863-FM | M33: A867-128 | N33: A867-128 | O33: N | P33: A873-567 | Q33: A873-34567 | R33: A873-34567 | S33: N | T33: N | U33: A877-ENG@16H | V33: A877-ENG@16H | W33: N | X33: A868-FM | Y33: A861- | AJ33: =COUNTIFS(D33:AG33,"<>"&"?",D33:AG33,"<>"&"",D33:AG33,"<>"&"fe",D33:AG33,"<>"&"vn") -> 15 | AK33: B1 B787/A321 | AL33: 0937387889 | AN33: 485 AC | AR33: 0
A34: 7 | B34: Hoàng Sơn Hà | C34: VAE00725 | D34: A862-@14H | E34: A869-EC@16H | F34: A869-EC@16H | G34: N | H34: A869-EC | I34: A864-128 | J34: A864-128 | K34: A863-128 | L34: N | M34: N | N34: A867-128 | O34: FE | P34: A873-128 | Q34: A873-128 | R34: A873-128 | S34: A873-ALL | T34: A877-ENG | U34: A877-ENG | V34: N | W34: N | X34: A868-34567 | Y34: A861- | Z34: FE | AA34: FE | AJ34: =COUNTIFS(D34:AG34,"<>"&"?",D34:AG34,"<>"&"",D34:AG34,"<>"&"fe",D34:AG34,"<>"&"vn") -> 16 | AK34: B1 787 | AL34: 0904321509 | AN34: 467 AC | AR34: 0
A35: 8 | B35: Nguyễn Văn Quyền | C35: VAE03234 | D35: HL8082-128 | E35: HL8082-ALL | F35: HL8082-ALL | G35: HL8082-ALL | H35: N | I35: A864-ALL@15H | J35: A864-ALL@14H | K35: A863-128 | L35: N | M35: A867-128 | N35: FE | O35: ĐG THAY CANG | P35: ĐG THAY CANG | Q35: FE | R35: ĐG THAY CANG | S35: A877-ENG@14H | T35: FE | U35: A877-FM | V35: Đ3 | W35: Đ3 | X35: N | Y35: EWIS | Z35: N | AA35: N | AF35: Thi CAAV | AG35: Thi CAAV | AJ35: =COUNTIFS(D35:AG35,"<>"&"?",D35:AG35,"<>"&"",D35:AG35,"<>"&"fe",D35:AG35,"<>"&"vn") -> 18 | AK35: B1 B787/A321 | AL35: 0902164495 | AN35: 1819 AC | AR35: 0
A36: 9 | B36: Hồ Sĩ Út | C36: VAE02854 | D36: A862-128 | E36: A869-EC | F36: A869-EC | G36: A869-EC | H36: A869-EC | I36: N | J36: A864-34567 | K36: A863-128 | L36: A863-128 | M36: A867-34567 | N36: DIFF A321 | O36: DIFF A321 | P36: DIFF A321 | Q36: DIFF A321 | R36: DIFF A321 | S36: FE | T36: DIFF A321 | U36: DIFF A321 | V36: DIFF A321 | W36: DIFF A321 | X36: DIFF A321 | Y36: A861- | AF36: DIFF A321 | AJ36: =COUNTIFS(D36:AG36,"<>"&"?",D36:AG36,"<>"&"",D36:AG36,"<>"&"fe",D36:AG36,"<>"&"vn") -> 21 | AK36: B1 787 | AL36: 0344242223 | AN36: 488 AC | AR36: 0
A37: 10 | B37: Lộc Đức Hiền | C37: VAE02379 | D37: N | E37: N | F37: A869-EC | G37: A869-EC | H37: VS ALL | I37: A864-128 | J37: A864-128 | K37: A863-34 | L37: N | M37: A867-128 | N37: A867-128 | O37: A867-128 | P37: N | Q37: A873-128 | R37: A873-128 | S37: A873-ALL | T37: A877-ENG@16H | U37: N | V37: A877-ENG | W37: N | X37: A868-128 | Y37: A861- | AF37: ATVSLD | AJ37: =COUNTIFS(D37:AG37,"<>"&"?",D37:AG37,"<>"&"",D37:AG37,"<>"&"fe",D37:AG37,"<>"&"vn") -> 17 | AK37: B1 787 | AL37: 0896961686 | AN37: 493 AC | AR37: 0
A38: 11 | B38: Dương Viết Trìu | C38: VAE03250 | D38: A862-34567 | E38: A869-EC@16H | F38: N | G38: A869-EC@16H | H38: N | I38: N | J38: A864-34567 | K38: A863-567 | L38: A863-34567 | M38: N | N38: A867-34567 | O38: A867-34567 | P38: A873-34 | Q38: A873-34567 | R38: N | S38: A873-ALL | T38: A615-AF | U38: N | V38: A877-ENG | W38: Đ3-SSAG | X38: A868-128 | Y38: EWIS | Z38: A861- | AJ38: =COUNTIFS(D38:AG38,"<>"&"?",D38:AG38,"<>"&"",D38:AG38,"<>"&"fe",D38:AG38,"<>"&"vn") -> 17 | AK38: B1 B787/A321 | AL38: 0983990518 | AN38: 1816 AC | AR38: 0
A39: 12 | B39: Vũ Văn Mạnh | C39: VAE03240 | D39: HL8082-128 | E39: A869-EC@16H | F39: A869-EC@16H | G39: GD | H39: A869-ALL | I39: A864-128 | J39: A864-128 | K39: N | L39: N | M39: Đ3 | N39: Đ3 | O39: Đ3 | P39: Đ3 | Q39: Đ3 | R39: Đ3 | S39: N | T39: A877-ENG@16H | U39: A877-ENG@16H | V39: N | W39: A877-ENG | X39: A868-34567 | Y39: A861- | AB39: ATVSLD | AJ39: =COUNTIFS(D39:AG39,"<>"&"?",D39:AG39,"<>"&"",D39:AG39,"<>"&"fe",D39:AG39,"<>"&"vn") -> 19 | AK39: B1 B787/A321 | AL39: 0968697183 | AN39: 1834 AC | AR39: 0
A40: 13 | B40: Nguyễn Sỹ Tứ | C40: VAE03275 | D40: A862-128 | E40: FE | F40: FE | G40: A869-W/O | H40: A869-ALL | I40: A864-34567 | J40: A864-34567 | K40: A863-128 | L40: FE | M40: Đ3 | N40: N | O40: Đ3 | P40: Đ3 | Q40: Đ3 | R40: Đ3 | S40: N | T40: A615-AF | U40: N | V40: FE | W40: A877-ENG | X40: A868-ALL 13H | Y40: A861- | AC40: ATVSLD | AF40: FE | AJ40: =COUNTIFS(D40:AG40,"<>"&"?",D40:AG40,"<>"&"",D40:AG40,"<>"&"fe",D40:AG40,"<>"&"vn") -> 16 | AK40: B1 B787/A321 | AL40: 0356134372 | AN40: 1817 AC | AR40: 0
A41: 14 | B41: Phạm Hồng Quân | C41: VAE01301 | D41: N | E41: A869-AVI | F41: A869-EC@16H | G41: A869-EC@16H | H41: N | I41: A864-AVI | J41: FE | K41: A863-AVI | L41: A863-AVI | M41: A867-AVI | N41: A867-AVI | O41: N | P41: A873-AVI | Q41: A873-AVI | R41: FE | S41: A873-AVI | T41: A615-AVI | U41: N | V41: A877-ENG | W41: A877-ENG | X41: A868-AVI | Y41: N | AB41: ATVSLD | AH41: FE | AJ41: =COUNTIFS(D41:AG41,"<>"&"?",D41:AG41,"<>"&"",D41:AG41,"<>"&"fe",D41:AG41,"<>"&"vn") -> 16 | AK41: B2 787 | AL41: 0983173064 | AN41: 706 AC | AR41: 0
...

Sheet 1 (2)
A1: HCM BASE MAINTENANCE CENTER | F1: CLICK ON A/C TO RETURN ROSTER | L1: BS-F 34
A2: DAILY MAINTENANCE DISTRIBUTION
A3: A/C: | B3: =LEFT(VLOOKUP("h*",ROSTER!D24:D70,1,0),6) -> HL8082 | E3: =ROSTER!D24 -> 46143 | I3: SHIFT:
B4: FOREMAN: | C4: =INDEX(ROSTER!$B$25:$B$150,MATCH("*FM1*",ROSTER!D$25:D$227,0),1) -> Hà Quang Vinh | D4: PHONE: | E4: =INDEX(ROSTER!$AL$25:$AL$211,MATCH('1 (2)'!C4,ROSTER!$B$25:$B$150,0),1) -> 0904298289 | I4: TECH SUPPORT | J4: =INDEX(ROSTER!$B$25:$B$150,MATCH("*TECH*",ROSTER!D$25:D$227,0),1) -> Huỳnh Tố Như | K4: PHONE: | L4: =INDEX(ROSTER!$AL$25:$AL$211,MATCH('1 (2)'!J4,ROSTER!$B$25:$B$150,0),1) -> 0702785789 | O4: Trực VS
B5: CRS C | C5: =INDEX(ROSTER!$B$25:$B$150,MATCH("*QC*",ROSTER!D$25:D$227,0),1) -> Trần Phương | D5: PHONE: | E5: =INDEX(ROSTER!$AL$25:$AL$211,MATCH('1 (2)'!C5,ROSTER!$B$25:$B$150,0),1) -> 84986222241 | I5: DOCK PLANNER: | J5: =INDEX(ROSTER!$B$25:$B$150,MATCH("*PPC*",ROSTER!D$25:D$227,0),1) -> Trần Hoàng Nhung | K5: PHONE: | L5: =INDEX(ROSTER!$AL$25:$AL$211,MATCH('1 (2)'!J5,ROSTER!$B$25:$B$150,0),1) -> 0906852989
A6: ORD | B6: NAME AND SURNAME | C6: VAECO ID | D6: POSITION | E6: PHONE | F6: REMARK | H6: ORD | I6: NAME AND SURNAME | J6: VAECO ID | K6: POSITION | L6: PHONE | M6: REMARK | O6: Leader/GSGT
B7: =$B$3&"-128" -> HL8082-128 | I7: =$B$3&"-34567" -> HL8082-34567 | O7: PI/Leader/GSGT
A8: =IF(B8="","",ROW(A1)) -> 1 | B8: {=IFERROR(INDEX(ROSTER!$B$24:$B$150,MATCH(1,INDEX(($B$7=ROSTER!D$24:D$150)*(COUNTIFS(B$7:B7,ROSTER!$B$24:$B$150)=0),0,1),0),1),"")} -> Nguyễn Đức Tuân | C8: =IFERROR(INDEX(ROSTER!$C$24:$C$150,MATCH('1 (2)'!$B8,ROSTER!$B$24:$B$150,0),1),"") -> VAE00732 | D8: =IFERROR(INDEX(ROSTER!$AK$23:$AK$150,MATCH('1 (2)'!$B8,ROSTER!$B$23:$B$150,0),1),"") -> B1 B787/ATR/A321 | E8: =IFERROR(INDEX(ROSTER!$AL$23:$AL$150,MATCH('1 (2)'!$B8,ROSTER!$B$23:$B$150,0),1),"") -> 0979747380 | F8: Leader/GSGT | H8: =IF(I8="","",ROW(A1)) -> 1 | I8: {=IFERROR(INDEX(ROSTER!$B$24:$B$150,MATCH(1,INDEX(($I$7=ROSTER!D$24:D$150)*(COUNTIFS(I$7:I7,ROSTER!$B$24:$B$150)=0),0,1),0),1),"")} -> Lê Thanh Hải | J8: =IFERROR(INDEX(ROSTER!$C$24:$C$150,MATCH('1 (2)'!$I8,ROSTER!$B$24:$B$150,0),1),"") -> VAE02718 | K8: =IFERROR(INDEX(ROSTER!$AK$23:$AK$150,MATCH('1 (2)'!$I8,ROSTER!$B$23:$B$150,0),1),"") -> B1 B787/A321 | L8: =IFERROR(INDEX(ROSTER!$AL$23:$AL$150,MATCH('1 (2)'!$I8,ROSTER!$B$23:$B$150,0),1),"") -> 0979690783 | M8: SAG | O8: Test ACT/EMT
A9: =IF(B9="","",ROW(A2)) -> 2 | B9: {=IFERROR(INDEX(ROSTER!$B$24:$B$150,MATCH(1,INDEX(($B$7=ROSTER!D$24:D$150)*(COUNTIFS(B$7:B8,ROSTER!$B$24:$B$150)=0),0,1),0),1),"")} -> Nguyễn Văn Quyền | C9: =IFERROR(INDEX(ROSTER!$C$24:$C$150,MATCH('1 (2)'!$B9,ROSTER!$B$24:$B$150,0),1),"") -> VAE03234 | D9: =IFERROR(INDEX(ROSTER!$AK$23:$AK$150,MATCH('1 (2)'!$B9,ROSTER!$B$23:$B$150,0),1),"") -> B1 B787/A321 | E9: =IFERROR(INDEX(ROSTER!$AL$23:$AL$150,MATCH('1 (2)'!$B9,ROSTER!$B$23:$B$150,0),1),"") -> 0902164495 | F9: Leader/GSGT | H9: =IF(I9="","",ROW(A2)) -> 2 | I9: {=IFERROR(INDEX(ROSTER!$B$24:$B$150,MATCH(1,INDEX(($I$7=ROSTER!D$24:D$150)*(COUNTIFS(I$7:I8,ROSTER!$B$24:$B$150)=0),0,1),0),1),"")} -> Đào Việt Hải | J9: =IFERROR(INDEX(ROSTER!$C$24:$C$150,MATCH('1 (2)'!$I9,ROSTER!$B$24:$B$150,0),1),"") -> VAE00708 | K9: =IFERROR(INDEX(ROSTER!$AK$23:$AK$150,MATCH('1 (2)'!$I9,ROSTER!$B$23:$B$150,0),1),"") -> B1 787 | L9: =IFERROR(INDEX(ROSTER!$AL$23:$AL$150,MATCH('1 (2)'!$I9,ROSTER!$B$23:$B$150,0),1),"") -> 0908630644 | M9: Leader/GSGT | O9: TERM
A10: =IF(B10="","",ROW(A3)) -> 3 | B10: {=IFERROR(INDEX(ROSTER!$B$24:$B$150,MATCH(1,INDEX(($B$7=ROSTER!D$24:D$150)*(COUNTIFS(B$7:B9,ROSTER!$B$24:$B$150)=0),0,1),0),1),"")} -> Vũ Văn Mạnh | C10: =IFERROR(INDEX(ROSTER!$C$24:$C$150,MATCH('1 (2)'!$B10,ROSTER!$B$24:$B$150,0),1),"") -> VAE03240 | D10: =IFERROR(INDEX(ROSTER!$AK$23:$AK$150,MATCH('1 (2)'!$B10,ROSTER!$B$23:$B$150,0),1),"") -> B1 B787/A321 | E10: =IFERROR(INDEX(ROSTER!$AL$23:$AL$150,MATCH('1 (2)'!$B10,ROSTER!$B$23:$B$150,0),1),"") -> 0968697183 | H10: =IF(I10="","",ROW(A3)) -> 3 | I10: {=IFERROR(INDEX(ROSTER!$B$24:$B$150,MATCH(1,INDEX(($I$7=ROSTER!D$24:D$150)*(COUNTIFS(I$7:I9,ROSTER!$B$24:$B$150)=0),0,1),0),1),"")} -> Võ Tiến Dũng | J10: =IFERROR(INDEX(ROSTER!$C$24:$C$150,MATCH('1 (2)'!$I10,ROSTER!$B$24:$B$150,0),1),"") -> VAE00749 | K10: =IFERROR(INDEX(ROSTER!$AK$23:$AK$150,MATCH('1 (2)'!$I10,ROSTER!$B$23:$B$150,0),1),"") -> QM 787 | L10: =IFERROR(INDEX(ROSTER!$AL$23:$AL$150,MATCH('1 (2)'!$I10,ROSTER!$B$23:$B$150,0),1),"") -> 0375121297 | O10: SAG
A11: =IF(B11="","",ROW(A4)) -> 4 | B11: {=IFERROR(INDEX(ROSTER!$B$24:$B$150,MATCH(1,INDEX(($B$7=ROSTER!D$24:D$150)*(COUNTIFS(B$7:B10,ROSTER!$B$24:$B$150)=0),0,1),0),1),"")} -> Đoàn Mạnh Quyết | C11: =IFERROR(INDEX(ROSTER!$C$24:$C$150,MATCH('1 (2)'!$B11,ROSTER!$B$24:$B$150,0),1),"") -> VAE00521 | D11: =IFERROR(INDEX(ROSTER!$AK$23:$AK$150,MATCH('1 (2)'!$B11,ROSTER!$B$23:$B$150,0),1),"") -> QM 787 | E11: =IFERROR(INDEX(ROSTER!$AL$23:$AL$150,MATCH('1 (2)'!$B11,ROSTER!$B$23:$B$150,0),1),"") -> 0979789920 | H11: =IF(I11="","",ROW(A4)) -> 4 | I11: {=IFERROR(INDEX(ROSTER!$B$24:$B$150,MATCH(1,INDEX(($I$7=ROSTER!D$24:D$150)*(COUNTIFS(I$7:I10,ROSTER!$B$24:$B$150)=0),0,1),0),1),"")} -> Nguyễn Sinh Thái | J11: =IFERROR(INDEX(ROSTER!$C$24:$C$150,MATCH('1 (2)'!$I11,ROSTER!$B$24:$B$150,0),1),"") -> VAE04208 | K11: =IFERROR(INDEX(ROSTER!$AK$23:$AK$150,MATCH('1 (2)'!$I11,ROSTER!$B$23:$B$150,0),1),"") -> 0 | L11: =IFERROR(INDEX(ROSTER!$AL$23:$AL$150,MATCH('1 (2)'!$I11,ROSTER!$B$23:$B$150,0),1),"") -> 0 | M11: Tool TS5/LOCAL
A12: =IF(B12="","",ROW(A5)) -> 5 | B12: {=IFERROR(INDEX(ROSTER!$B$24:$B$150,MATCH(1,INDEX(($B$7=ROSTER!D$24:D$150)*(COUNTIFS(B$7:B11,ROSTER!$B$24:$B$150)=0),0,1),0),1),"")} -> Nguyễn Phan Hoàng Long | C12: =IFERROR(INDEX(ROSTER!$C$24:$C$150,MATCH('1 (2)'!$B12,ROSTER!$B$24:$B$150,0),1),"") -> VAE03596 | D12: =IFERROR(INDEX(ROSTER!$AK$23:$AK$150,MATCH('1 (2)'!$B12,ROSTER!$B$23:$B$150,0),1),"") -> QM AF | E12: =IFERROR(INDEX(ROSTER!$AL$23:$AL$150,MATCH('1 (2)'!$B12,ROSTER!$B$23:$B$150,0),1),"") -> 0967103203 | H12: =IF(I12="","",ROW(A5)) -> 5 | I12: {=IFERROR(INDEX(ROSTER!$B$24:$B$150,MATCH(1,INDEX(($I$7=ROSTER!D$24:D$150)*(COUNTIFS(I$7:I11,ROSTER!$B$24:$B$150)=0),0,1),0),1),"")} -> Thái Quang Anh | J12: =IFERROR(INDEX(ROSTER!$C$24:$C$150,MATCH('1 (2)'!$I12,ROSTER!$B$24:$B$150,0),1),"") -> VAE04252 | K12: =IFERROR(INDEX(ROSTER!$AK$23:$AK$150,MATCH('1 (2)'!$I12,ROSTER!$B$23:$B$150,0),1),"") -> 0 | L12: =IFERROR(INDEX(ROSTER!$AL$23:$AL$150,MATCH('1 (2)'!$I12,ROSTER!$B$23:$B$150,0),1),"") -> 0 | M12: Trực VS
A13: =IF(B13="","",ROW(A6)) -> 6 | B13: {=IFERROR(INDEX(ROSTER!$B$24:$B$150,MATCH(1,INDEX(($B$7=ROSTER!D$24:D$150)*(COUNTIFS(B$7:B12,ROSTER!$B$24:$B$150)=0),0,1),0),1),"")} -> Nguyễn An Bình | C13: =IFERROR(INDEX(ROSTER!$C$24:$C$150,MATCH('1 (2)'!$B13,ROSTER!$B$24:$B$150,0),1),"") -> VAE04051 | D13: =IFERROR(INDEX(ROSTER!$AK$23:$AK$150,MATCH('1 (2)'!$B13,ROSTER!$B$23:$B$150,0),1),"") -> MECH | E13: =IFERROR(INDEX(ROSTER!$AL$23:$AL$150,MATCH('1 (2)'!$B13,ROSTER!$B$23:$B$150,0),1),"") -> 0852188678 | F13: Tool TS5/LOCAL | H13: =IF(I13="","",ROW(A6)) -> 6 | I13: {=IFERROR(INDEX(ROSTER!$B$24:$B$150,MATCH(1,INDEX(($I$7=ROSTER!D$24:D$150)*(COUNTIFS(I$7:I12,ROSTER!$B$24:$B$150)=0),0,1),0),1),"")} -> Bùi Phú Duy | J13: =IFERROR(INDEX(ROSTER!$C$24:$C$150,MATCH('1 (2)'!$I13,ROSTER!$B$24:$B$150,0),1),"") -> VAE04017 | K13: =IFERROR(INDEX(ROSTER!$AK$23:$AK$150,MATCH('1 (2)'!$I13,ROSTER!$B$23:$B$150,0),1),"") -> 0 | L13: =IFERROR(INDEX(ROSTER!$AL$23:$AL$150,MATCH('1 (2)'!$I13,ROSTER!$B$23:$B$150,0),1),"") -> 0 | M13: Trực VS
A14: =IF(B14="","",ROW(A7)) -> 7 | B14: {=IFERROR(INDEX(ROSTER!$B$24:$B$150,MATCH(1,INDEX(($B$7=ROSTER!D$24:D$150)*(COUNTIFS(B$7:B13,ROSTER!$B$24:$B$150)=0),0,1),0),1),"")} -> Nguyễn Thành Trung | C14: =IFERROR(INDEX(ROSTER!$C$24:$C$150,MATCH('1 (2)'!$B14,ROSTER!$B$24:$B$150,0),1),"") -> VAE04031 | D14: =IFERROR(INDEX(ROSTER!$AK$23:$AK$150,MATCH('1 (2)'!$B14,ROSTER!$B$23:$B$150,0),1),"") -> MECH | E14: =IFERROR(INDEX(ROSTER!$AL$23:$AL$150,MATCH('1 (2)'!$B14,ROSTER!$B$23:$B$150,0),1),"") -> 0962516841 | F14: Tool TS5/LOCAL | H14: =IF(I14="","",ROW(A7)) -> 7 | I14: {=IFERROR(INDEX(ROSTER!$B$24:$B$150,MATCH(1,INDEX(($I$7=ROSTER!D$24:D$150)*(COUNTIFS(I$7:I13,ROSTER!$B$24:$B$150)=0),0,1),0),1),"")} -> Nguyễn Thiên Đình | J14: =IFERROR(INDEX(ROSTER!$C$24:$C$150,MATCH('1 (2)'!$I14,ROSTER!$B$24:$B$150,0),1),"") -> VAE03084 | K14: =IFERROR(INDEX(ROSTER!$AK$23:$AK$150,MATCH('1 (2)'!$I14,ROSTER!$B$23:$B$150,0),1),"") -> 0 | L14: =IFERROR(INDEX(ROSTER!$AL$23:$AL$150,MATCH('1 (2)'!$I14,ROSTER!$B$23:$B$150,0),1),"") -> 0
A15: =IF(B15="","",ROW(A8)) -> 8 | B15: {=IFERROR(INDEX(ROSTER!$B$24:$B$150,MATCH(1,INDEX(($B$7=ROSTER!D$24:D$150)*(COUNTIFS(B$7:B14,ROSTER!$B$24:$B$150)=0),0,1),0),1),"")} -> Nguyễn Quang Vinh | C15: =IFERROR(INDEX(ROSTER!$C$24:$C$150,MATCH('1 (2)'!$B15,ROSTER!$B$24:$B$150,0),1),"") -> VAE04206 | D15: =IFERROR(INDEX(ROSTER!$AK$23:$AK$150,MATCH('1 (2)'!$B15,ROSTER!$B$23:$B$150,0),1),"") -> 0 | E15: =IFERROR(INDEX(ROSTER!$AL$23:$AL$150,MATCH('1 (2)'!$B15,ROSTER!$B$23:$B$150,0),1),"") -> 0 | F15: Trực VS | H15: =IF(I15="","",ROW(A8)) | I15: {=IFERROR(INDEX(ROSTER!$B$24:$B$150,MATCH(1,INDEX(($I$7=ROSTER!D$24:D$150)*(COUNTIFS(I$7:I14,ROSTER!$B$24:$B$150)=0),0,1),0),1),"")} | J15: =IFERROR(INDEX(ROSTER!$C$24:$C$150,MATCH('1 (2)'!$I15,ROSTER!$B$24:$B$150,0),1),"") | K15: =IFERROR(INDEX(ROSTER!$AK$23:$AK$150,MATCH('1 (2)'!$I15,ROSTER!$B$23:$B$150,0),1),"") | L15: =IFERROR(INDEX(ROSTER!$AL$23:$AL$150,MATCH('1 (2)'!$I15,ROSTER!$B$23:$B$150,0),1),"")
A16: =IF(B16="","",ROW(A9)) -> 9 | B16: {=IFERROR(INDEX(ROSTER!$B$24:$B$150,MATCH(1,INDEX(($B$7=ROSTER!D$24:D$150)*(COUNTIFS(B$7:B15,ROSTER!$B$24:$B$150)=0),0,1),0),1),"")} -> Đặng Phương Nam | C16: =IFERROR(INDEX(ROSTER!$C$24:$C$150,MATCH('1 (2)'!$B16,ROSTER!$B$24:$B$150,0),1),"") -> VAE04213 | D16: =IFERROR(INDEX(ROSTER!$AK$23:$AK$150,MATCH('1 (2)'!$B16,ROSTER!$B$23:$B$150,0),1),"") -> 0 | E16: =IFERROR(INDEX(ROSTER!$AL$23:$AL$150,MATCH('1 (2)'!$B16,ROSTER!$B$23:$B$150,0),1),"") -> 0 | H16: =IF(I16="","",ROW(A9)) | I16: {=IFERROR(INDEX(ROSTER!$B$24:$B$150,MATCH(1,INDEX(($I$7=ROSTER!D$24:D$150)*(COUNTIFS(I$7:I15,ROSTER!$B$24:$B$150)=0),0,1),0),1),"")} | J16: =IFERROR(INDEX(ROSTER!$C$24:$C$150,MATCH('1 (2)'!$I16,ROSTER!$B$24:$B$150,0),1),"") | K16: =IFERROR(INDEX(ROSTER!$AK$23:$AK$150,MATCH('1 (2)'!$I16,ROSTER!$B$23:$B$150,0),1),"") | L16: =IFERROR(INDEX(ROSTER!$AL$23:$AL$150,MATCH('1 (2)'!$I16,ROSTER!$B$23:$B$150,0),1),"")
A17: =IF(B17="","",ROW(A10)) | B17: {=IFERROR(INDEX(ROSTER!$B$24:$B$150,MATCH(1,INDEX(($B$7=ROSTER!D$24:D$150)*(COUNTIFS(B$7:B16,ROSTER!$B$24:$B$150)=0),0,1),0),1),"")} | C17: =IFERROR(INDEX(ROSTER!$C$24:$C$150,MATCH('1 (2)'!$B17,ROSTER!$B$24:$B$150,0),1),"") | D17: =IFERROR(INDEX(ROSTER!$AK$23:$AK$150,MATCH('1 (2)'!$B17,ROSTER!$B$23:$B$150,0),1),"") | E17: =IFERROR(INDEX(ROSTER!$AL$23:$AL$150,MATCH('1 (2)'!$B17,ROSTER!$B$23:$B$150,0),1),"") | H17: =IF(I17="","",ROW(A10)) | I17: {=IFERROR(INDEX(ROSTER!$B$24:$B$150,MATCH(1,INDEX(($I$7=ROSTER!D$24:D$150)*(COUNTIFS(I$7:I16,ROSTER!$B$24:$B$150)=0),0,1),0),1),"")} | J17: =IFERROR(INDEX(ROSTER!$C$24:$C$150,MATCH('1 (2)'!$I17,ROSTER!$B$24:$B$150,0),1),"") | K17: =IFERROR(INDEX(ROSTER!$AK$23:$AK$150,MATCH('1 (2)'!$I17,ROSTER!$B$23:$B$150,0),1),"") | L17: =IFERROR(INDEX(ROSTER!$AL$23:$AL$150,MATCH('1 (2)'!$I17,ROSTER!$B$23:$B$150,0),1),"")
A18: =IF(B18="","",ROW(A11)) | B18: {=IFERROR(INDEX(ROSTER!$B$24:$B$150,MATCH(1,INDEX(($B$7=ROSTER!D$24:D$150)*(COUNTIFS(B$7:B17,ROSTER!$B$24:$B$150)=0),0,1),0),1),"")} | C18: =IFERROR(INDEX(ROSTER!$C$24:$C$150,MATCH('1 (2)'!$B18,ROSTER!$B$24:$B$150,0),1),"") | D18: =IFERROR(INDEX(ROSTER!$AK$23:$AK$150,MATCH('1 (2)'!$B18,ROSTER!$B$23:$B$150,0),1),"") | E18: =IFERROR(INDEX(ROSTER!$AL$23:$AL$150,MATCH('1 (2)'!$B18,ROSTER!$B$23:$B$150,0),1),"") | H18: =IF(I18="","",ROW(A11)) | I18: {=IFERROR(INDEX(ROSTER!$B$24:$B$150,MATCH(1,INDEX(($I$7=ROSTER!D$24:D$150)*(COUNTIFS(I$7:I17,ROSTER!$B$24:$B$150)=0),0,1),0),1),"")} | J18: =IFERROR(INDEX(ROSTER!$C$24:$C$150,MATCH('1 (2)'!$I18,ROSTER!$B$24:$B$150,0),1),"") | K18: =IFERROR(INDEX(ROSTER!$AK$23:$AK$150,MATCH('1 (2)'!$I18,ROSTER!$B$23:$B$150,0),1),"") | L18: =IFERROR(INDEX(ROSTER!$AL$23:$AL$150,MATCH('1 (2)'!$I18,ROSTER!$B$23:$B$150,0),1),"")
A19: =IF(B19="","",ROW(A12)) | B19: {=IFERROR(INDEX(ROSTER!$B$24:$B$150,MATCH(1,INDEX(($B$7=ROSTER!D$24:D$150)*(COUNTIFS(B$7:B18,ROSTER!$B$24:$B$150)=0),0,1),0),1),"")} | C19: =IFERROR(INDEX(ROSTER!$C$24:$C$150,MATCH('1 (2)'!$B19,ROSTER!$B$24:$B$150,0),1),"") | D19: =IFERROR(INDEX(ROSTER!$AK$23:$AK$150,MATCH('1 (2)'!$B19,ROSTER!$B$23:$B$150,0),1),"") | E19: =IFERROR(INDEX(ROSTER!$AL$23:$AL$150,MATCH('1 (2)'!$B19,ROSTER!$B$23:$B$150,0),1),"") | H19: =IF(I19="","",ROW(A12)) | I19: {=IFERROR(INDEX(ROSTER!$B$24:$B$150,MATCH(1,INDEX(($I$7=ROSTER!D$24:D$150)*(COUNTIFS(I$7:I18,ROSTER!$B$24:$B$150)=0),0,1),0),1),"")} | J19: =IFERROR(INDEX(ROSTER!$C$24:$C$150,MATCH('1 (2)'!$I19,ROSTER!$B$24:$B$150,0),1),"") | K19: =IFERROR(INDEX(ROSTER!$AK$23:$AK$150,MATCH('1 (2)'!$I19,ROSTER!$B$23:$B$150,0),1),"") | L19: =IFERROR(INDEX(ROSTER!$AL$23:$AL$150,MATCH('1 (2)'!$I19,ROSTER!$B$23:$B$150,0),1),"")
B20: =$B$3&"-AVI" -> HL8082-AVI | H20: =IF(I20="","",ROW(A13)) | I20: {=IFERROR(INDEX(ROSTER!$B$24:$B$150,MATCH(1,INDEX(($I$7=ROSTER!D$24:D$150)*(COUNTIFS(I$7:I19,ROSTER!$B$24:$B$150)=0),0,1),0),1),"")} | J20: =IFERROR(INDEX(ROSTER!$C$24:$C$150,MATCH('1 (2)'!$I20,ROSTER!$B$24:$B$150,0),1),"") | K20: =IFERROR(INDEX(ROSTER!$AK$23:$AK$150,MATCH('1 (2)'!$I20,ROSTER!$B$23:$B$150,0),1),"") | L20: =IFERROR(INDEX(ROSTER!$AL$23:$AL$150,MATCH('1 (2)'!$I20,ROSTER!$B$23:$B$150,0),1),"")
A21: =IF(B21="","",ROW(A1)) -> 1 | B21: {=IFERROR(INDEX(ROSTER!$B$24:$B$150,MATCH(1,INDEX(($B$20=ROSTER!D$24:D$150)*(COUNTIFS(B$7:B20,ROSTER!$B$24:$B$150)=0),0,1),0),1),"")} -> Đậu Thanh Tâm | C21: =IFERROR(INDEX(ROSTER!$C$24:$C$150,MATCH('1 (2)'!$B21,ROSTER!$B$24:$B$150,0),1),"") -> VAE00742 | D21: =IFERROR(INDEX(ROSTER!$AK$23:$AK$150,MATCH('1 (2)'!$B21,ROSTER!$B$23:$B$150,0),1),"") -> B2 787 | E21: =IFERROR(INDEX(ROSTER!$AL$23:$AL$150,MATCH('1 (2)'!$B21,ROSTER!$B$23:$B$150,0),1),"") -> 0903804857 | H21: =IF(I21="","",ROW(A14)) | I21: {=IFERROR(INDEX(ROSTER!$B$24:$B$150,MATCH(1,INDEX(($I$7=ROSTER!D$24:D$150)*(COUNTIFS(I$7:I20,ROSTER!$B$24:$B$150)=0),0,1),0),1),"")} | J21: =IFERROR(INDEX(ROSTER!$C$24:$C$150,MATCH('1 (2)'!$I21,ROSTER!$B$24:$B$150,0),1),"") | K21: =IFERROR(INDEX(ROSTER!$AK$23:$AK$150,MATCH('1 (2)'!$I21,ROSTER!$B$23:$B$150,0),1),"") | L21: =IFERROR(INDEX(ROSTER!$AL$23:$AL$150,MATCH('1 (2)'!$I21,ROSTER!$B$23:$B$150,0),1),"")
A22: =IF(B22="","",ROW(A2)) -> 2 | B22: {=IFERROR(INDEX(ROSTER!$B$24:$B$150,MATCH(1,INDEX(($B$20=ROSTER!D$24:D$150)*(COUNTIFS(B$7:B21,ROSTER!$B$24:$B$150)=0),0,1),0),1),"")} -> Đoàn Văn Tú | C22: =IFERROR(INDEX(ROSTER!$C$24:$C$150,MATCH('1 (2)'!$B22,ROSTER!$B$24:$B$150,0),1),"") -> VAE00256 | D22: =IFERROR(INDEX(ROSTER!$AK$23:$AK$150,MATCH('1 (2)'!$B22,ROSTER!$B$23:$B$150,0),1),"") -> B2 B787/A321 | E22: =IFERROR(INDEX(ROSTER!$AL$23:$AL$70,MATCH('1 (2)'!$B22,ROSTER!$B$23:$B$150,0),1),"") -> 0917384394 | H22: =IF(I22="","",ROW(A15)) | I22: {=IFERROR(INDEX(ROSTER!$B$24:$B$150,MATCH(1,INDEX(($I$7=ROSTER!D$24:D$150)*(COUNTIFS(I$7:I21,ROSTER!$B$24:$B$150)=0),0,1),0),1),"")} | J22: =IFERROR(INDEX(ROSTER!$C$24:$C$150,MATCH('1 (2)'!$I22,ROSTER!$B$24:$B$150,0),1),"") | K22: =IFERROR(INDEX(ROSTER!$AK$23:$AK$150,MATCH('1 (2)'!$I22,ROSTER!$B$23:$B$150,0),1),"") | L22: =IFERROR(INDEX(ROSTER!$AL$23:$AL$150,MATCH('1 (2)'!$I22,ROSTER!$B$23:$B$150,0),1),"")
A23: =IF(B23="","",ROW(A3)) -> 3 | B23: {=IFERROR(INDEX(ROSTER!$B$24:$B$150,MATCH(1,INDEX(($B$20=ROSTER!D$24:D$150)*(COUNTIFS(B$7:B22,ROSTER!$B$24:$B$150)=0),0,1),0),1),"")} -> Đinh Vương Anh Thông | C23: =IFERROR(INDEX(ROSTER!$C$24:$C$150,MATCH('1 (2)'!$B23,ROSTER!$B$24:$B$150,0),1),"") -> VAE03590 | D23: =IFERROR(INDEX(ROSTER!$AK$23:$AK$150,MATCH('1 (2)'!$B23,ROSTER!$B$23:$B$150,0),1),"") -> EA 787/321 | E23: =IFERROR(INDEX(ROSTER!$AL$23:$AL$70,MATCH('1 (2)'!$B23,ROSTER!$B$23:$B$150,0),1),"") -> 0943213677 | F23: Trực VS | H23: =IF(I23="","",ROW(A16)) | I23: {=IFERROR(INDEX(ROSTER!$B$24:$B$150,MATCH(1,INDEX(($I$7=ROSTER!D$24:D$150)*(COUNTIFS(I$7:I22,ROSTER!$B$24:$B$150)=0),0,1),0),1),"")} | J23: =IFERROR(INDEX(ROSTER!$C$24:$C$150,MATCH('1 (2)'!$I23,ROSTER!$B$24:$B$150,0),1),"") | K23: =IFERROR(INDEX(ROSTER!$AK$23:$AK$150,MATCH('1 (2)'!$I23,ROSTER!$B$23:$B$150,0),1),"") | L23: =IFERROR(INDEX(ROSTER!$AL$23:$AL$150,MATCH('1 (2)'!$I23,ROSTER!$B$23:$B$150,0),1),"")
A24: =IF(B24="","",ROW(A4)) -> 4 | B24: {=IFERROR(INDEX(ROSTER!$B$24:$B$150,MATCH(1,INDEX(($B$20=ROSTER!D$24:D$150)*(COUNTIFS(B$7:B23,ROSTER!$B$24:$B$150)=0),0,1),0),1),"")} -> Nguyễn Trương Tân | C24: =IFERROR(INDEX(ROSTER!$C$24:$C$150,MATCH('1 (2)'!$B24,ROSTER!$B$24:$B$150,0),1),"") -> VAE04019 | D24: =IFERROR(INDEX(ROSTER!$AK$23:$AK$150,MATCH('1 (2)'!$B24,ROSTER!$B$23:$B$150,0),1),"") -> EA 787 | E24: =IFERROR(INDEX(ROSTER!$AL$23:$AL$70,MATCH('1 (2)'!$B24,ROSTER!$B$23:$B$150,0),1),"") -> 0902827093 | F24: Tool TS5/LOCAL | H24: =IF(I24="","",ROW(A17)) | I24: {=IFERROR(INDEX(ROSTER!$B$24:$B$150,MATCH(1,INDEX(($I$7=ROSTER!D$24:D$150)*(COUNTIFS(I$7:I23,ROSTER!$B$24:$B$150)=0),0,1),0),1),"")} | J24: =IFERROR(INDEX(ROSTER!$C$24:$C$150,MATCH('1 (2)'!$I24,ROSTER!$B$24:$B$150,0),1),"") | K24: =IFERROR(INDEX(ROSTER!$AK$23:$AK$150,MATCH('1 (2)'!$I24,ROSTER!$B$23:$B$150,0),1),"") | L24: =IFERROR(INDEX(ROSTER!$AL$23:$AL$150,MATCH('1 (2)'!$I24,ROSTER!$B$23:$B$150,0),1),"")
A25: =IF(B25="","",ROW(A5)) -> 5 | B25: {=IFERROR(INDEX(ROSTER!$B$24:$B$150,MATCH(1,INDEX(($B$20=ROSTER!D$24:D$150)*(COUNTIFS(B$7:B24,ROSTER!$B$24:$B$150)=0),0,1),0),1),"")} -> Nguyễn Hữu Hoàng | C25: =IFERROR(INDEX(ROSTER!$C$24:$C$150,MATCH('1 (2)'!$B25,ROSTER!$B$24:$B$150,0),1),"") -> VAE03618 | D25: =IFERROR(INDEX(ROSTER!$AK$23:$AK$150,MATCH('1 (2)'!$B25,ROSTER!$B$23:$B$150,0),1),"") -> EA 787/321 | E25: =IFERROR(INDEX(ROSTER!$AL$23:$AL$70,MATCH('1 (2)'!$B25,ROSTER!$B$23:$B$150,0),1),"") -> 0937919456 | F25: Leader/GSGT | H25: =IF(I25="","",ROW(A18)) | I25: {=IFERROR(INDEX(ROSTER!$B$24:$B$150,MATCH(1,INDEX(($I$7=ROSTER!D$24:D$150)*(COUNTIFS(I$7:I24,ROSTER!$B$24:$B$150)=0),0,1),0),1),"")} | J25: =IFERROR(INDEX(ROSTER!$C$24:$C$150,MATCH('1 (2)'!$I25,ROSTER!$B$24:$B$150,0),1),"") | K25: =IFERROR(INDEX(ROSTER!$AK$23:$AK$150,MATCH('1 (2)'!$I25,ROSTER!$B$23:$B$150,0),1),"") | L25: =IFERROR(INDEX(ROSTER!$AL$23:$AL$150,MATCH('1 (2)'!$I25,ROSTER!$B$23:$B$150,0),1),"")
A26: =IF(B26="","",ROW(A6)) -> 6 | B26: {=IFERROR(INDEX(ROSTER!$B$24:$B$150,MATCH(1,INDEX(($B$20=ROSTER!D$24:D$150)*(COUNTIFS(B$7:B25,ROSTER!$B$24:$B$150)=0),0,1),0),1),"")} -> Trần Anh Tuấn PKT | C26: =IFERROR(INDEX(ROSTER!$C$24:$C$150,MATCH('1 (2)'!$B26,ROSTER!$B$24:$B$150,0),1),"") -> VAE01351 | D26: =IFERROR(INDEX(ROSTER!$AK$23:$AK$150,MATCH('1 (2)'!$B26,ROSTER!$B$23:$B$150,0),1),"") -> B2 787/321 | E26: =IFERROR(INDEX(ROSTER!$AL$23:$AL$150,MATCH('1 (2)'!$B26,ROSTER!$B$23:$B$150,0),1),"") -> 0918056705 | H26: =IF(I26="","",ROW(A19)) | I26: {=IFERROR(INDEX(ROSTER!$B$24:$B$150,MATCH(1,INDEX(($I$7=ROSTER!D$24:D$150)*(COUNTIFS(I$7:I25,ROSTER!$B$24:$B$150)=0),0,1),0),1),"")} | J26: =IFERROR(INDEX(ROSTER!$C$24:$C$150,MATCH('1 (2)'!$I26,ROSTER!$B$24:$B$150,0),1),"") | K26: =IFERROR(INDEX(ROSTER!$AK$23:$AK$150,MATCH('1 (2)'!$I26,ROSTER!$B$23:$B$150,0),1),"") | L26: =IFERROR(INDEX(ROSTER!$AL$23:$AL$150,MATCH('1 (2)'!$I26,ROSTER!$B$23:$B$150,0),1),"")
A27: =IF(B27="","",ROW(A7)) | B27: {=IFERROR(INDEX(ROSTER!$B$24:$B$150,MATCH(1,INDEX(($B$20=ROSTER!D$24:D$150)*(COUNTIFS(B$7:B26,ROSTER!$B$24:$B$150)=0),0,1),0),1),"")} | C27: =IFERROR(INDEX(ROSTER!$C$24:$C$150,MATCH('1 (2)'!$B27,ROSTER!$B$24:$B$150,0),1),"") | D27: =IFERROR(INDEX(ROSTER!$AK$23:$AK$150,MATCH('1 (2)'!$B27,ROSTER!$B$23:$B$150,0),1),"") | E27: =IFERROR(INDEX(ROSTER!$AL$23:$AL$70,MATCH('1 (2)'!$B27,ROSTER!$B$23:$B$150,0),1),"") | H27: =IF(I27="","",ROW(A20)) | I27: {=IFERROR(INDEX(ROSTER!$B$24:$B$150,MATCH(1,INDEX(($I$7=ROSTER!D$24:D$150)*(COUNTIFS(I$7:I26,ROSTER!$B$24:$B$150)=0),0,1),0),1),"")} | J27: =IFERROR(INDEX(ROSTER!$C$24:$C$150,MATCH('1 (2)'!$I27,ROSTER!$B$24:$B$150,0),1),"") | K27: =IFERROR(INDEX(ROSTER!$AK$23:$AK$150,MATCH('1 (2)'!$I27,ROSTER!$B$23:$B$150,0),1),"") | L27: =IFERROR(INDEX(ROSTER!$AL$23:$AL$150,MATCH('1 (2)'!$I27,ROSTER!$B$23:$B$150,0),1),"")
A28: =IF(B28="","",ROW(A8)) | B28: {=IFERROR(INDEX(ROSTER!$B$24:$B$150,MATCH(1,INDEX(($B$20=ROSTER!D$24:D$150)*(COUNTIFS(B$7:B27,ROSTER!$B$24:$B$150)=0),0,1),0),1),"")} | C28: =IFERROR(INDEX(ROSTER!$C$24:$C$150,MATCH('1 (2)'!$B28,ROSTER!$B$24:$B$150,0),1),"") | D28: =IFERROR(INDEX(ROSTER!$AK$23:$AK$150,MATCH('1 (2)'!$B28,ROSTER!$B$23:$B$150,0),1),"") | E28: =IFERROR(INDEX(ROSTER!$AL$23:$AL$150,MATCH('1 (2)'!$B28,ROSTER!$B$23:$B$150,0),1),"") | H28: =IF(I28="","",ROW(A21)) | I28: {=IFERROR(INDEX(ROSTER!$B$24:$B$150,MATCH(1,INDEX(($I$7=ROSTER!D$24:D$150)*(COUNTIFS(I$7:I27,ROSTER!$B$24:$B$150)=0),0,1),0),1),"")} | J28: =IFERROR(INDEX(ROSTER!$C$24:$C$150,MATCH('1 (2)'!$I28,ROSTER!$B$24:$B$150,0),1),"") | K28: =IFERROR(INDEX(ROSTER!$AK$23:$AK$150,MATCH('1 (2)'!$I28,ROSTER!$B$23:$B$150,0),1),"") | L28: =IFERROR(INDEX(ROSTER!$AL$23:$AL$150,MATCH('1 (2)'!$I28,ROSTER!$B$23:$B$150,0),1),"")
A29: =IF(B29="","",ROW(A9)) | B29: {=IFERROR(INDEX(ROSTER!$B$24:$B$150,MATCH(1,INDEX(($B$20=ROSTER!D$24:D$150)*(COUNTIFS(B$7:B28,ROSTER!$B$24:$B$150)=0),0,1),0),1),"")} | C29: =IFERROR(INDEX(ROSTER!$C$24:$C$150,MATCH('1 (2)'!$B29,ROSTER!$B$24:$B$150,0),1),"") | D29: =IFERROR(INDEX(ROSTER!$AK$23:$AK$150,MATCH('1 (2)'!$B29,ROSTER!$B$23:$B$150,0),1),"") | E29: =IFERROR(INDEX(ROSTER!$AL$23:$AL$70,MATCH('1 (2)'!$B29,ROSTER!$B$23:$B$150,0),1),"") | H29: =IF(I29="","",ROW(A22)) | I29: {=IFERROR(INDEX(ROSTER!$B$24:$B$150,MATCH(1,INDEX(($I$7=ROSTER!D$24:D$150)*(COUNTIFS(I$7:I28,ROSTER!$B$24:$B$150)=0),0,1),0),1),"")} | J29: =IFERROR(INDEX(ROSTER!$C$24:$C$150,MATCH('1 (2)'!$I29,ROSTER!$B$24:$B$150,0),1),"") | K29: =IFERROR(INDEX(ROSTER!$AK$23:$AK$150,MATCH('1 (2)'!$I29,ROSTER!$B$23:$B$150,0),1),"") | L29: =IFERROR(INDEX(ROSTER!$AL$23:$AL$150,MATCH('1 (2)'!$I29,ROSTER!$B$23:$B$150,0),1),"")
H54: =IF(I54="","",ROW(A48)) | I54: {=IFERROR(INDEX(ROSTER!$B$24:$B$150,MATCH(1,INDEX(($I$7=ROSTER!D$24:D$150)*(COUNTIFS(I$7:I53,ROSTER!$B$24:$B$150)=0),0,1),0),1),"")} | J54: =IFERROR(INDEX(ROSTER!$C$24:$C$150,MATCH('1 (2)'!$I54,ROSTER!$B$24:$B$150,0),1),"") | K54: =IFERROR(INDEX(ROSTER!$AK$23:$AK$150,MATCH('1 (2)'!$I54,ROSTER!$B$23:$B$150,0),1),"") | L54: =IFERROR(INDEX(ROSTER!$AL$23:$AL$150,MATCH('1 (2)'!$I54,ROSTER!$B$23:$B$150,0),1),"")
H55: =IF(I55="","",ROW(A49)) | I55: {=IFERROR(INDEX(ROSTER!$B$24:$B$150,MATCH(1,INDEX(($I$7=ROSTER!D$24:D$150)*(COUNTIFS(I$7:I54,ROSTER!$B$24:$B$150)=0),0,1),0),1),"")} | J55: =IFERROR(INDEX(ROSTER!$C$24:$C$150,MATCH('1 (2)'!$I55,ROSTER!$B$24:$B$150,0),1),"") | K55: =IFERROR(INDEX(ROSTER!$AK$23:$AK$150,MATCH('1 (2)'!$I55,ROSTER!$B$23:$B$150,0),1),"") | L55: =IFERROR(INDEX(ROSTER!$AL$23:$AL$150,MATCH('1 (2)'!$I55,ROSTER!$B$23:$B$150,0),1),"")
H56: =IF(I56="","",ROW(A50)) | I56: {=IFERROR(INDEX(ROSTER!$B$24:$B$150,MATCH(1,INDEX(($I$7=ROSTER!D$24:D$150)*(COUNTIFS(I$7:I55,ROSTER!$B$24:$B$150)=0),0,1),0),1),"")} | J56: =IFERROR(INDEX(ROSTER!$C$24:$C$150,MATCH('1 (2)'!$I56,ROSTER!$B$24:$B$150,0),1),"") | K56: =IFERROR(INDEX(ROSTER!$AK$23:$AK$150,MATCH('1 (2)'!$I56,ROSTER!$B$23:$B$150,0),1),"") | L56: =IFERROR(INDEX(ROSTER!$AL$23:$AL$150,MATCH('1 (2)'!$I56,ROSTER!$B$23:$B$150,0),1),"")
H57: =IF(I57="","",ROW(A51)) | I57: {=IFERROR(INDEX(ROSTER!$B$24:$B$150,MATCH(1,INDEX(($I$7=ROSTER!D$24:D$150)*(COUNTIFS(I$7:I56,ROSTER!$B$24:$B$150)=0),0,1),0),1),"")} | J57: =IFERROR(INDEX(ROSTER!$C$24:$C$150,MATCH('1 (2)'!$I57,ROSTER!$B$24:$B$150,0),1),"") | K57: =IFERROR(INDEX(ROSTER!$AK$23:$AK$150,MATCH('1 (2)'!$I57,ROSTER!$B$23:$B$150,0),1),"") | L57: =IFERROR(INDEX(ROSTER!$AL$23:$AL$150,MATCH('1 (2)'!$I57,ROSTER!$B$23:$B$150,0),1),"")
H58: =IF(I58="","",ROW(A52)) | I58: {=IFERROR(INDEX(ROSTER!$B$24:$B$150,MATCH(1,INDEX(($I$7=ROSTER!D$24:D$150)*(COUNTIFS(I$7:I57,ROSTER!$B$24:$B$150)=0),0,1),0),1),"")} | J58: =IFERROR(INDEX(ROSTER!$C$24:$C$150,MATCH('1 (2)'!$I58,ROSTER!$B$24:$B$150,0),1),"") | K58: =IFERROR(INDEX(ROSTER!$AK$23:$AK$150,MATCH('1 (2)'!$I58,ROSTER!$B$23:$B$150,0),1),"") | L58: =IFERROR(INDEX(ROSTER!$AL$23:$AL$150,MATCH('1 (2)'!$I58,ROSTER!$B$23:$B$150,0),1),"")
H59: =IF(I59="","",ROW(A53)) | I59: {=IFERROR(INDEX(ROSTER!$B$24:$B$150,MATCH(1,INDEX(($I$7=ROSTER!D$24:D$150)*(COUNTIFS(I$7:I58,ROSTER!$B$24:$B$150)=0),0,1),0),1),"")} | J59: =IFERROR(INDEX(ROSTER!$C$24:$C$150,MATCH('1 (2)'!$I59,ROSTER!$B$24:$B$150,0),1),"") | K59: =IFERROR(INDEX(ROSTER!$AK$23:$AK$150,MATCH('1 (2)'!$I59,ROSTER!$B$23:$B$150,0),1),"") | L59: =IFERROR(INDEX(ROSTER!$AL$23:$AL$150,MATCH('1 (2)'!$I59,ROSTER!$B$23:$B$150,0),1),"")
H60: =IF(I60="","",ROW(A54)) | I60: {=IFERROR(INDEX(ROSTER!$B$24:$B$150,MATCH(1,INDEX(($I$7=ROSTER!D$24:D$150)*(COUNTIFS(I$7:I59,ROSTER!$B$24:$B$150)=0),0,1),0),1),"")} | J60: =IFERROR(INDEX(ROSTER!$C$24:$C$150,MATCH('1 (2)'!$I60,ROSTER!$B$24:$B$150,0),1),"") | K60: =IFERROR(INDEX(ROSTER!$AK$23:$AK$150,MATCH('1 (2)'!$I60,ROSTER!$B$23:$B$150,0),1),"") | L60: =IFERROR(INDEX(ROSTER!$AL$23:$AL$150,MATCH('1 (2)'!$I60,ROSTER!$B$23:$B$150,0),1),"")
H61: =IF(I61="","",ROW(A55)) | I61: {=IFERROR(INDEX(ROSTER!$B$24:$B$150,MATCH(1,INDEX(($I$7=ROSTER!D$24:D$150)*(COUNTIFS(I$7:I60,ROSTER!$B$24:$B$150)=0),0,1),0),1),"")} | J61: =IFERROR(INDEX(ROSTER!$C$24:$C$150,MATCH('1 (2)'!$I61,ROSTER!$B$24:$B$150,0),1),"") | K61: =IFERROR(INDEX(ROSTER!$AK$23:$AK$150,MATCH('1 (2)'!$I61,ROSTER!$B$23:$B$150,0),1),"") | L61: =IFERROR(INDEX(ROSTER!$AL$23:$AL$150,MATCH('1 (2)'!$I61,ROSTER!$B$23:$B$150,0),1),"")
H62: =IF(I62="","",ROW(A56)) | I62: {=IFERROR(INDEX(ROSTER!$B$24:$B$150,MATCH(1,INDEX(($I$7=ROSTER!D$24:D$150)*(COUNTIFS(I$7:I61,ROSTER!$B$24:$B$150)=0),0,1),0),1),"")} | J62: =IFERROR(INDEX(ROSTER!$C$24:$C$150,MATCH('1 (2)'!$I62,ROSTER!$B$24:$B$150,0),1),"") | K62: =IFERROR(INDEX(ROSTER!$AK$23:$AK$150,MATCH('1 (2)'!$I62,ROSTER!$B$23:$B$150,0),1),"") | L62: =IFERROR(INDEX(ROSTER!$AL$23:$AL$150,MATCH('1 (2)'!$I62,ROSTER!$B$23:$B$150,0),1),"")
H63: =IF(I63="","",ROW(A57)) | I63: {=IFERROR(INDEX(ROSTER!$B$24:$B$150,MATCH(1,INDEX(($I$7=ROSTER!D$24:D$150)*(COUNTIFS(I$7:I62,ROSTER!$B$24:$B$150)=0),0,1),0),1),"")} | J63: =IFERROR(INDEX(ROSTER!$C$24:$C$150,MATCH('1 (2)'!$I63,ROSTER!$B$24:$B$150,0),1),"") | K63: =IFERROR(INDEX(ROSTER!$AK$23:$AK$150,MATCH('1 (2)'!$I63,ROSTER!$B$23:$B$150,0),1),"") | L63: =IFERROR(INDEX(ROSTER!$AL$23:$AL$150,MATCH('1 (2)'!$I63,ROSTER!$B$23:$B$150,0),1),"")
H64: =IF(I64="","",ROW(A58)) | I64: {=IFERROR(INDEX(ROSTER!$B$24:$B$150,MATCH(1,INDEX(($I$7=ROSTER!D$24:D$150)*(COUNTIFS(I$7:I63,ROSTER!$B$24:$B$150)=0),0,1),0),1),"")} | J64: =IFERROR(INDEX(ROSTER!$C$24:$C$150,MATCH('1 (2)'!$I64,ROSTER!$B$24:$B$150,0),1),"") | K64: =IFERROR(INDEX(ROSTER!$AK$23:$AK$150,MATCH('1 (2)'!$I64,ROSTER!$B$23:$B$150,0),1),"") | L64: =IFERROR(INDEX(ROSTER!$AL$23:$AL$150,MATCH('1 (2)'!$I64,ROSTER!$B$23:$B$150,0),1),"")
...

Sheet 1
A1: HCM BASE MAINTENANCE CENTER | F1: CLICK ON A/C TO RETURN ROSTER | L1: BS-F 34
A2: DAILY MAINTENANCE DISTRIBUTION
A3: A/C: | B3: =LEFT(VLOOKUP("A*",ROSTER!D24:D70,1,0),4) -> A862 | E3: =ROSTER!D24 -> 46143 | I3: SHIFT:
B4: FOREMAN: | C4: =INDEX(ROSTER!$B$25:$B$150,MATCH("*FM*",ROSTER!D$25:D$227,0),1) -> Hứa Quang Trung | D4: PHONE: | E4: =INDEX(ROSTER!$AL$25:$AL$211,MATCH('1'!C4,ROSTER!$B$25:$B$150,0),1) -> 0937387889 | F4: SAG | I4: TECH SUPPORT | J4: =INDEX(ROSTER!$B$25:$B$150,MATCH("*TECH*",ROSTER!D$25:D$227,0),1) -> Huỳnh Tố Như | K4: PHONE: | L4: =INDEX(ROSTER!$AL$25:$AL$211,MATCH('1'!J4,ROSTER!$B$25:$B$150,0),1) -> 0702785789 | O4: Trực VS
B5: CRS C | C5: =INDEX(ROSTER!$B$25:$B$150,MATCH("*QC*",ROSTER!D$25:D$227,0),1) -> Trần Phương | D5: PHONE: | E5: =INDEX(ROSTER!$AL$25:$AL$211,MATCH('1'!C5,ROSTER!$B$25:$B$150,0),1) -> 84986222241 | I5: DOCK PLANNER: | J5: =INDEX(ROSTER!$B$25:$B$150,MATCH("*PPC1*",ROSTER!D$25:D$227,0),1) -> Vũ Tuấn Tú | K5: PHONE: | L5: =INDEX(ROSTER!$AL$25:$AL$211,MATCH('1'!J5,ROSTER!$B$25:$B$150,0),1) -> 0774768007
A6: ORD | B6: NAME AND SURNAME | C6: VAECO ID | D6: POSITION | E6: PHONE | F6: REMARK | H6: ORD | I6: NAME AND SURNAME | J6: VAECO ID | K6: POSITION | L6: PHONE | M6: REMARK | O6: Leader/GSGT
B7: =$B$3&"-128" -> A862-128 | I7: =$B$3&"-34567" -> A862-34567 | O7: PI/Leader/GSGT
A8: =IF(B8="","",ROW(A1)) -> 1 | B8: {=IFERROR(INDEX(ROSTER!$B$24:$B$150,MATCH(1,INDEX(($B$7=ROSTER!D$24:D$150)*(COUNTIFS(B$7:B7,ROSTER!$B$24:$B$150)=0),0,1),0),1),"")} -> Hồ Sĩ Út | C8: =IFERROR(INDEX(ROSTER!$C$24:$C$150,MATCH('1'!$B8,ROSTER!$B$24:$B$150,0),1),"") -> VAE02854 | D8: =IFERROR(INDEX(ROSTER!$AK$23:$AK$150,MATCH('1'!$B8,ROSTER!$B$23:$B$150,0),1),"") -> B1 787 | E8: =IFERROR(INDEX(ROSTER!$AL$23:$AL$150,MATCH('1'!$B8,ROSTER!$B$23:$B$150,0),1),"") -> 0344242223 | F8: Leader/GSGT | H8: =IF(I8="","",ROW(A1)) -> 1 | I8: {=IFERROR(INDEX(ROSTER!$B$24:$B$150,MATCH(1,INDEX(($I$7=ROSTER!D$24:D$150)*(COUNTIFS(I$7:I7,ROSTER!$B$24:$B$150)=0),0,1),0),1),"")} -> Phạm Ngọc Anh | J8: =IFERROR(INDEX(ROSTER!$C$24:$C$150,MATCH('1'!$I8,ROSTER!$B$24:$B$150,0),1),"") -> VAE01348 | K8: =IFERROR(INDEX(ROSTER!$AK$23:$AK$150,MATCH('1'!$I8,ROSTER!$B$23:$B$150,0),1),"") -> B1 787 | L8: =IFERROR(INDEX(ROSTER!$AL$23:$AL$150,MATCH('1'!$I8,ROSTER!$B$23:$B$150,0),1),"") -> 0902153933 | M8: Leader 34/GSGT | O8: Test ACT/EMT
A9: =IF(B9="","",ROW(A2)) -> 2 | B9: {=IFERROR(INDEX(ROSTER!$B$24:$B$150,MATCH(1,INDEX(($B$7=ROSTER!D$24:D$150)*(COUNTIFS(B$7:B8,ROSTER!$B$24:$B$150)=0),0,1),0),1),"")} -> Nguyễn Sỹ Tứ | C9: =IFERROR(INDEX(ROSTER!$C$24:$C$150,MATCH('1'!$B9,ROSTER!$B$24:$B$150,0),1),"") -> VAE03275 | D9: =IFERROR(INDEX(ROSTER!$AK$23:$AK$150,MATCH('1'!$B9,ROSTER!$B$23:$B$150,0),1),"") -> B1 B787/A321 | E9: =IFERROR(INDEX(ROSTER!$AL$23:$AL$150,MATCH('1'!$B9,ROSTER!$B$23:$B$150,0),1),"") -> 0356134372 | F9: SAG | H9: =IF(I9="","",ROW(A2)) -> 2 | I9: {=IFERROR(INDEX(ROSTER!$B$24:$B$150,MATCH(1,INDEX(($I$7=ROSTER!D$24:D$150)*(COUNTIFS(I$7:I8,ROSTER!$B$24:$B$150)=0),0,1),0),1),"")} -> Dương Viết Trìu | J9: =IFERROR(INDEX(ROSTER!$C$24:$C$150,MATCH('1'!$I9,ROSTER!$B$24:$B$150,0),1),"") -> VAE03250 | K9: =IFERROR(INDEX(ROSTER!$AK$23:$AK$150,MATCH('1'!$I9,ROSTER!$B$23:$B$150,0),1),"") -> B1 B787/A321 | L9: =IFERROR(INDEX(ROSTER!$AL$23:$AL$150,MATCH('1'!$I9,ROSTER!$B$23:$B$150,0),1),"") -> 0983990518 | M9: Leader 567/GSGT | O9: TERM
A10: =IF(B10="","",ROW(A3)) -> 3 | B10: {=IFERROR(INDEX(ROSTER!$B$24:$B$150,MATCH(1,INDEX(($B$7=ROSTER!D$24:D$150)*(COUNTIFS(B$7:B9,ROSTER!$B$24:$B$150)=0),0,1),0),1),"")} -> Phạm Minh Tuấn | C10: =IFERROR(INDEX(ROSTER!$C$24:$C$150,MATCH('1'!$B10,ROSTER!$B$24:$B$150,0),1),"") -> VAE00763 | D10: =IFERROR(INDEX(ROSTER!$AK$23:$AK$150,MATCH('1'!$B10,ROSTER!$B$23:$B$150,0),1),"") -> QM 787 | E10: =IFERROR(INDEX(ROSTER!$AL$23:$AL$150,MATCH('1'!$B10,ROSTER!$B$23:$B$150,0),1),"") -> 0903128278 | H10: =IF(I10="","",ROW(A3)) -> 3 | I10: {=IFERROR(INDEX(ROSTER!$B$24:$B$150,MATCH(1,INDEX(($I$7=ROSTER!D$24:D$150)*(COUNTIFS(I$7:I9,ROSTER!$B$24:$B$150)=0),0,1),0),1),"")} -> Nguyễn Văn Thái | J10: =IFERROR(INDEX(ROSTER!$C$24:$C$150,MATCH('1'!$I10,ROSTER!$B$24:$B$150,0),1),"") -> VAE03591 | K10: =IFERROR(INDEX(ROSTER!$AK$23:$AK$150,MATCH('1'!$I10,ROSTER!$B$23:$B$150,0),1),"") -> QM PP | L10: =IFERROR(INDEX(ROSTER!$AL$23:$AL$150,MATCH('1'!$I10,ROSTER!$B$23:$B$150,0),1),"") -> 0938235487 | O10: SAG
A11: =IF(B11="","",ROW(A4)) -> 4 | B11: {=IFERROR(INDEX(ROSTER!$B$24:$B$150,MATCH(1,INDEX(($B$7=ROSTER!D$24:D$150)*(COUNTIFS(B$7:B10,ROSTER!$B$24:$B$150)=0),0,1),0),1),"")} -> Nguyễn Anh Tuấn | C11: =IFERROR(INDEX(ROSTER!$C$24:$C$150,MATCH('1'!$B11,ROSTER!$B$24:$B$150,0),1),"") -> VAE02373 | D11: =IFERROR(INDEX(ROSTER!$AK$23:$AK$150,MATCH('1'!$B11,ROSTER!$B$23:$B$150,0),1),"") -> QM 787 | E11: =IFERROR(INDEX(ROSTER!$AL$23:$AL$150,MATCH('1'!$B11,ROSTER!$B$23:$B$150,0),1),"") -> 0988034352 | H11: =IF(I11="","",ROW(A4)) -> 4 | I11: {=IFERROR(INDEX(ROSTER!$B$24:$B$150,MATCH(1,INDEX(($I$7=ROSTER!D$24:D$150)*(COUNTIFS(I$7:I10,ROSTER!$B$24:$B$150)=0),0,1),0),1),"")} -> Nguyễn Mạnh Phố | J11: =IFERROR(INDEX(ROSTER!$C$24:$C$150,MATCH('1'!$I11,ROSTER!$B$24:$B$150,0),1),"") -> VAE03605 | K11: =IFERROR(INDEX(ROSTER!$AK$23:$AK$150,MATCH('1'!$I11,ROSTER!$B$23:$B$150,0),1),"") -> QM AF | L11: =IFERROR(INDEX(ROSTER!$AL$23:$AL$150,MATCH('1'!$I11,ROSTER!$B$23:$B$150,0),1),"") -> 0829109358 | M11: Tool TS5/LOCAL
A12: =IF(B12="","",ROW(A5)) -> 5 | B12: {=IFERROR(INDEX(ROSTER!$B$24:$B$150,MATCH(1,INDEX(($B$7=ROSTER!D$24:D$150)*(COUNTIFS(B$7:B11,ROSTER!$B$24:$B$150)=0),0,1),0),1),"")} -> Phạm Hùng | C12: =IFERROR(INDEX(ROSTER!$C$24:$C$150,MATCH('1'!$B12,ROSTER!$B$24:$B$150,0),1),"") -> VAE01771 | D12: =IFERROR(INDEX(ROSTER!$AK$23:$AK$150,MATCH('1'!$B12,ROSTER!$B$23:$B$150,0),1),"") -> QM AF | E12: =IFERROR(INDEX(ROSTER!$AL$23:$AL$150,MATCH('1'!$B12,ROSTER!$B$23:$B$150,0),1),"") -> 0908489886 | F12: Tool TS5/LOCAL | H12: =IF(I12="","",ROW(A5)) -> 5 | I12: {=IFERROR(INDEX(ROSTER!$B$24:$B$150,MATCH(1,INDEX(($I$7=ROSTER!D$24:D$150)*(COUNTIFS(I$7:I11,ROSTER!$B$24:$B$150)=0),0,1),0),1),"")} -> Dương Minh Tuấn | J12: =IFERROR(INDEX(ROSTER!$C$24:$C$150,MATCH('1'!$I12,ROSTER!$B$24:$B$150,0),1),"") -> VAE04035 | K12: =IFERROR(INDEX(ROSTER!$AK$23:$AK$150,MATCH('1'!$I12,ROSTER!$B$23:$B$150,0),1),"") -> MECH | L12: =IFERROR(INDEX(ROSTER!$AL$23:$AL$150,MATCH('1'!$I12,ROSTER!$B$23:$B$150,0),1),"") -> 0938930981 | M12: Tool TS5/LOCAL
A13: =IF(B13="","",ROW(A6)) -> 6 | B13: {=IFERROR(INDEX(ROSTER!$B$24:$B$150,MATCH(1,INDEX(($B$7=ROSTER!D$24:D$150)*(COUNTIFS(B$7:B12,ROSTER!$B$24:$B$150)=0),0,1),0),1),"")} -> Vũ Quang Vinh | C13: =IFERROR(INDEX(ROSTER!$C$24:$C$150,MATCH('1'!$B13,ROSTER!$B$24:$B$150,0),1),"") -> VAE03617 | D13: =IFERROR(INDEX(ROSTER!$AK$23:$AK$150,MATCH('1'!$B13,ROSTER!$B$23:$B$150,0),1),"") -> QM AF | E13: =IFERROR(INDEX(ROSTER!$AL$23:$AL$150,MATCH('1'!$B13,ROSTER!$B$23:$B$150,0),1),"") -> 0773781627 | F13: Tool TS5/LOCAL | H13: =IF(I13="","",ROW(A6)) -> 6 | I13: {=IFERROR(INDEX(ROSTER!$B$24:$B$150,MATCH(1,INDEX(($I$7=ROSTER!D$24:D$150)*(COUNTIFS(I$7:I12,ROSTER!$B$24:$B$150)=0),0,1),0),1),"")} -> Nguyễn Duy Khang | J13: =IFERROR(INDEX(ROSTER!$C$24:$C$150,MATCH('1'!$I13,ROSTER!$B$24:$B$150,0),1),"") -> VAE03607 | K13: =IFERROR(INDEX(ROSTER!$AK$23:$AK$150,MATCH('1'!$I13,ROSTER!$B$23:$B$150,0),1),"") -> QM AF | L13: =IFERROR(INDEX(ROSTER!$AL$23:$AL$150,MATCH('1'!$I13,ROSTER!$B$23:$B$150,0),1),"") -> 0935594624 | M13: Trực VS
A14: =IF(B14="","",ROW(A7)) -> 7 | B14: {=IFERROR(INDEX(ROSTER!$B$24:$B$150,MATCH(1,INDEX(($B$7=ROSTER!D$24:D$150)*(COUNTIFS(B$7:B13,ROSTER!$B$24:$B$150)=0),0,1),0),1),"")} -> Thân Minh Nguyên | C14: =IFERROR(INDEX(ROSTER!$C$24:$C$150,MATCH('1'!$B14,ROSTER!$B$24:$B$150,0),1),"") -> VAE04211 | D14: =IFERROR(INDEX(ROSTER!$AK$23:$AK$150,MATCH('1'!$B14,ROSTER!$B$23:$B$150,0),1),"") -> MECH | E14: =IFERROR(INDEX(ROSTER!$AL$23:$AL$150,MATCH('1'!$B14,ROSTER!$B$23:$B$150,0),1),"") -> 0366492128 | F14: Tool TS5/LOCAL | H14: =IF(I14="","",ROW(A7)) -> 7 | I14: {=IFERROR(INDEX(ROSTER!$B$24:$B$150,MATCH(1,INDEX(($I$7=ROSTER!D$24:D$150)*(COUNTIFS(I$7:I13,ROSTER!$B$24:$B$150)=0),0,1),0),1),"")} -> Nguyễn Hữu Thắng | J14: =IFERROR(INDEX(ROSTER!$C$24:$C$150,MATCH('1'!$I14,ROSTER!$B$24:$B$150,0),1),"") -> VAE03620 | K14: =IFERROR(INDEX(ROSTER!$AK$23:$AK$150,MATCH('1'!$I14,ROSTER!$B$23:$B$150,0),1),"") -> EA 787/321 | L14: =IFERROR(INDEX(ROSTER!$AL$23:$AL$150,MATCH('1'!$I14,ROSTER!$B$23:$B$150,0),1),"") -> 0865855733 | M14: Trực VS
A15: =IF(B15="","",ROW(A8)) -> 8 | B15: {=IFERROR(INDEX(ROSTER!$B$24:$B$150,MATCH(1,INDEX(($B$7=ROSTER!D$24:D$150)*(COUNTIFS(B$7:B14,ROSTER!$B$24:$B$150)=0),0,1),0),1),"")} -> Lê Minh CHâu | C15: =IFERROR(INDEX(ROSTER!$C$24:$C$150,MATCH('1'!$B15,ROSTER!$B$24:$B$150,0),1),"") -> VAE04037 | D15: =IFERROR(INDEX(ROSTER!$AK$23:$AK$150,MATCH('1'!$B15,ROSTER!$B$23:$B$150,0),1),"") -> 0 | E15: =IFERROR(INDEX(ROSTER!$AL$23:$AL$150,MATCH('1'!$B15,ROSTER!$B$23:$B$150,0),1),"") -> 0 | F15: EMT/ACT | H15: =IF(I15="","",ROW(A8)) -> 8 | I15: {=IFERROR(INDEX(ROSTER!$B$24:$B$150,MATCH(1,INDEX(($I$7=ROSTER!D$24:D$150)*(COUNTIFS(I$7:I14,ROSTER!$B$24:$B$150)=0),0,1),0),1),"")} -> Lê Trần Thiên Cương | J15: =IFERROR(INDEX(ROSTER!$C$24:$C$150,MATCH('1'!$I15,ROSTER!$B$24:$B$150,0),1),"") -> VAE04203 | K15: =IFERROR(INDEX(ROSTER!$AK$23:$AK$150,MATCH('1'!$I15,ROSTER!$B$23:$B$150,0),1),"") -> MECH | L15: =IFERROR(INDEX(ROSTER!$AL$23:$AL$150,MATCH('1'!$I15,ROSTER!$B$23:$B$150,0),1),"") -> 0867773318
A16: =IF(B16="","",ROW(A9)) -> 9 | B16: {=IFERROR(INDEX(ROSTER!$B$24:$B$150,MATCH(1,INDEX(($B$7=ROSTER!D$24:D$150)*(COUNTIFS(B$7:B15,ROSTER!$B$24:$B$150)=0),0,1),0),1),"")} -> Võ Trọng Sơn | C16: =IFERROR(INDEX(ROSTER!$C$24:$C$150,MATCH('1'!$B16,ROSTER!$B$24:$B$150,0),1),"") -> VAE04039 | D16: =IFERROR(INDEX(ROSTER!$AK$23:$AK$150,MATCH('1'!$B16,ROSTER!$B$23:$B$150,0),1),"") -> 0 | E16: =IFERROR(INDEX(ROSTER!$AL$23:$AL$150,MATCH('1'!$B16,ROSTER!$B$23:$B$150,0),1),"") -> 0 | F16: Trực VS | H16: =IF(I16="","",ROW(A9)) -> 9 | I16: {=IFERROR(INDEX(ROSTER!$B$24:$B$150,MATCH(1,INDEX(($I$7=ROSTER!D$24:D$150)*(COUNTIFS(I$7:I15,ROSTER!$B$24:$B$150)=0),0,1),0),1),"")} -> Hồ Zy Đan | J16: =IFERROR(INDEX(ROSTER!$C$24:$C$150,MATCH('1'!$I16,ROSTER!$B$24:$B$150,0),1),"") -> VAE04209 | K16: =IFERROR(INDEX(ROSTER!$AK$23:$AK$150,MATCH('1'!$I16,ROSTER!$B$23:$B$150,0),1),"") -> MECH | L16: =IFERROR(INDEX(ROSTER!$AL$23:$AL$150,MATCH('1'!$I16,ROSTER!$B$23:$B$150,0),1),"") -> 0348081971
A17: =IF(B17="","",ROW(A10)) | B17: {=IFERROR(INDEX(ROSTER!$B$24:$B$150,MATCH(1,INDEX(($B$7=ROSTER!D$24:D$150)*(COUNTIFS(B$7:B16,ROSTER!$B$24:$B$150)=0),0,1),0),1),"")} | C17: =IFERROR(INDEX(ROSTER!$C$24:$C$150,MATCH('1'!$B17,ROSTER!$B$24:$B$150,0),1),"") | D17: =IFERROR(INDEX(ROSTER!$AK$23:$AK$150,MATCH('1'!$B17,ROSTER!$B$23:$B$150,0),1),"") | E17: =IFERROR(INDEX(ROSTER!$AL$23:$AL$150,MATCH('1'!$B17,ROSTER!$B$23:$B$150,0),1),"") | H17: =IF(I17="","",ROW(A10)) -> 10 | I17: {=IFERROR(INDEX(ROSTER!$B$24:$B$150,MATCH(1,INDEX(($I$7=ROSTER!D$24:D$150)*(COUNTIFS(I$7:I16,ROSTER!$B$24:$B$150)=0),0,1),0),1),"")} -> Trần Thành Danh | J17: =IFERROR(INDEX(ROSTER!$C$24:$C$150,MATCH('1'!$I17,ROSTER!$B$24:$B$150,0),1),"") -> VAE04207 | K17: =IFERROR(INDEX(ROSTER!$AK$23:$AK$150,MATCH('1'!$I17,ROSTER!$B$23:$B$150,0),1),"") -> 0 | L17: =IFERROR(INDEX(ROSTER!$AL$23:$AL$150,MATCH('1'!$I17,ROSTER!$B$23:$B$150,0),1),"") -> 0
A18: =IF(B18="","",ROW(A12)) | B18: {=IFERROR(INDEX(ROSTER!$B$24:$B$150,MATCH(1,INDEX(($B$7=ROSTER!D$24:D$150)*(COUNTIFS(B$7:B17,ROSTER!$B$24:$B$150)=0),0,1),0),1),"")} | C18: =IFERROR(INDEX(ROSTER!$C$24:$C$150,MATCH('1'!$B18,ROSTER!$B$24:$B$150,0),1),"") | D18: =IFERROR(INDEX(ROSTER!$AK$23:$AK$150,MATCH('1'!$B18,ROSTER!$B$23:$B$150,0),1),"") | E18: =IFERROR(INDEX(ROSTER!$AL$23:$AL$150,MATCH('1'!$B18,ROSTER!$B$23:$B$150,0),1),"") | H18: =IF(I18="","",ROW(A12)) | I18: {=IFERROR(INDEX(ROSTER!$B$24:$B$150,MATCH(1,INDEX(($I$7=ROSTER!D$24:D$150)*(COUNTIFS(I$7:I17,ROSTER!$B$24:$B$150)=0),0,1),0),1),"")} | J18: =IFERROR(INDEX(ROSTER!$C$24:$C$150,MATCH('1'!$I18,ROSTER!$B$24:$B$150,0),1),"") | K18: =IFERROR(INDEX(ROSTER!$AK$23:$AK$150,MATCH('1'!$I18,ROSTER!$B$23:$B$150,0),1),"") | L18: =IFERROR(INDEX(ROSTER!$AL$23:$AL$150,MATCH('1'!$I18,ROSTER!$B$23:$B$150,0),1),"")
B19: =$B$3&"-AVI" -> A862-AVI | H19: =IF(I19="","",ROW(A10)) | I19: {=IFERROR(INDEX(ROSTER!$B$24:$B$150,MATCH(1,INDEX(($I$7=ROSTER!D$24:D$150)*(COUNTIFS(I$7:I18,ROSTER!$B$24:$B$150)=0),0,1),0),1),"")} | J19: =IFERROR(INDEX(ROSTER!$C$24:$C$150,MATCH('1'!$I19,ROSTER!$B$24:$B$150,0),1),"") | K19: =IFERROR(INDEX(ROSTER!$AK$23:$AK$150,MATCH('1'!$I19,ROSTER!$B$23:$B$150,0),1),"") | L19: =IFERROR(INDEX(ROSTER!$AL$23:$AL$150,MATCH('1'!$I19,ROSTER!$B$23:$B$150,0),1),"")
A20: =IF(B20="","",ROW(A1)) -> 1 | B20: {=IFERROR(INDEX(ROSTER!$B$24:$B$150,MATCH(1,INDEX(($B$19=ROSTER!D$24:D$150)*(COUNTIFS(B$7:B19,ROSTER!$B$24:$B$150)=0),0,1),0),1),"")} -> Nguyễn Tiến Thịnh | C20: =IFERROR(INDEX(ROSTER!$C$24:$C$150,MATCH('1'!$B20,ROSTER!$B$24:$B$150,0),1),"") -> VAE02736 | D20: =IFERROR(INDEX(ROSTER!$AK$23:$AK$150,MATCH('1'!$B20,ROSTER!$B$23:$B$150,0),1),"") -> B2 787 | E20: =IFERROR(INDEX(ROSTER!$AL$23:$AL$150,MATCH('1'!$B20,ROSTER!$B$23:$B$150,0),1),"") -> 0907669646 | F20: Leader/GSGT | I20: =$B$3&"-@14H" -> A862-@14H
A21: =IF(B21="","",ROW(A2)) -> 2 | B21: {=IFERROR(INDEX(ROSTER!$B$24:$B$150,MATCH(1,INDEX(($B$19=ROSTER!D$24:D$150)*(COUNTIFS(B$7:B20,ROSTER!$B$24:$B$150)=0),0,1),0),1),"")} -> Nguyễn Minh Đức | C21: =IFERROR(INDEX(ROSTER!$C$24:$C$150,MATCH('1'!$B21,ROSTER!$B$24:$B$150,0),1),"") -> VAE04018 | D21: =IFERROR(INDEX(ROSTER!$AK$23:$AK$150,MATCH('1'!$B21,ROSTER!$B$23:$B$150,0),1),"") -> EA 787 | E21: =IFERROR(INDEX(ROSTER!$AL$23:$AL$70,MATCH('1'!$B21,ROSTER!$B$23:$B$150,0),1),"") -> 0907548998 | F21: Tool TS5/LOCAL | H21: =IF(I21="","",ROW(A1)) -> 1 | I21: {=IFERROR(INDEX(ROSTER!$B$24:$B$150,MATCH(1,INDEX(($I$20=ROSTER!D$24:D$150)*(COUNTIFS(I$7:I20,ROSTER!$B$24:$B$150)=0),0,1),0),1),"")} -> Hoàng Sơn Hà | J21: =IFERROR(INDEX(ROSTER!$C$24:$C$150,MATCH('1'!$I21,ROSTER!$B$24:$B$150,0),1),"") -> VAE00725 | K21: =IFERROR(INDEX(ROSTER!$AK$23:$AK$150,MATCH('1'!$I21,ROSTER!$B$23:$B$150,0),1),"") -> B1 787 | L21: =IFERROR(INDEX(ROSTER!$AL$23:$AL$150,MATCH('1'!$I21,ROSTER!$B$23:$B$150,0),1),"") -> 0904321509 | M21: Leader/GSGT
A22: =IF(B22="","",ROW(A3)) -> 3 | B22: {=IFERROR(INDEX(ROSTER!$B$24:$B$150,MATCH(1,INDEX(($B$19=ROSTER!D$24:D$150)*(COUNTIFS(B$7:B21,ROSTER!$B$24:$B$150)=0),0,1),0),1),"")} -> Phạm Bá Khánh | C22: =IFERROR(INDEX(ROSTER!$C$24:$C$150,MATCH('1'!$B22,ROSTER!$B$24:$B$150,0),1),"") -> VAE02476 | D22: =IFERROR(INDEX(ROSTER!$AK$23:$AK$150,MATCH('1'!$B22,ROSTER!$B$23:$B$150,0),1),"") -> B2 787 | E22: =IFERROR(INDEX(ROSTER!$AL$23:$AL$150,MATCH('1'!$B22,ROSTER!$B$23:$B$150,0),1),"") -> 0 | F22: EMT/ACT | H22: =IF(I22="","",ROW(A2)) -> 2 | I22: {=IFERROR(INDEX(ROSTER!$B$24:$B$150,MATCH(1,INDEX(($I$20=ROSTER!D$24:D$150)*(COUNTIFS(I$7:I21,ROSTER!$B$24:$B$150)=0),0,1),0),1),"")} -> Đặng Quốc Tú | J22: =IFERROR(INDEX(ROSTER!$C$24:$C$150,MATCH('1'!$I22,ROSTER!$B$24:$B$150,0),1),"") -> VAE00733 | K22: =IFERROR(INDEX(ROSTER!$AK$23:$AK$150,MATCH('1'!$I22,ROSTER!$B$23:$B$150,0),1),"") -> QM 787 | L22: =IFERROR(INDEX(ROSTER!$AL$23:$AL$150,MATCH('1'!$I22,ROSTER!$B$23:$B$150,0),1),"") -> 0988110968
A23: =IF(B23="","",ROW(A4)) -> 4 | B23: {=IFERROR(INDEX(ROSTER!$B$24:$B$150,MATCH(1,INDEX(($B$19=ROSTER!D$24:D$150)*(COUNTIFS(B$7:B22,ROSTER!$B$24:$B$150)=0),0,1),0),1),"")} -> Lê Minh Lộc | C23: =IFERROR(INDEX(ROSTER!$C$24:$C$150,MATCH('1'!$B23,ROSTER!$B$24:$B$150,0),1),"") -> VAE04030 | D23: =IFERROR(INDEX(ROSTER!$AK$23:$AK$150,MATCH('1'!$B23,ROSTER!$B$23:$B$150,0),1),"") -> 0 | E23: =IFERROR(INDEX(ROSTER!$AL$23:$AL$70,MATCH('1'!$B23,ROSTER!$B$23:$B$150,0),1),"") | F23: Trực VS | H23: =IF(I23="","",ROW(A3)) -> 3 | I23: {=IFERROR(INDEX(ROSTER!$B$24:$B$150,MATCH(1,INDEX(($I$20=ROSTER!D$24:D$150)*(COUNTIFS(I$7:I22,ROSTER!$B$24:$B$150)=0),0,1),0),1),"")} -> Lê Hà Vinh | J23: =IFERROR(INDEX(ROSTER!$C$24:$C$150,MATCH('1'!$I23,ROSTER!$B$24:$B$150,0),1),"") -> VAE03603 | K23: =IFERROR(INDEX(ROSTER!$AK$23:$AK$150,MATCH('1'!$I23,ROSTER!$B$23:$B$150,0),1),"") -> QM PP | L23: =IFERROR(INDEX(ROSTER!$AL$23:$AL$150,MATCH('1'!$I23,ROSTER!$B$23:$B$150,0),1),"") -> 0963322827
A24: =IF(B24="","",ROW(A5)) | B24: {=IFERROR(INDEX(ROSTER!$B$24:$B$150,MATCH(1,INDEX(($B$19=ROSTER!D$24:D$150)*(COUNTIFS(B$7:B23,ROSTER!$B$24:$B$150)=0),0,1),0),1),"")} | C24: =IFERROR(INDEX(ROSTER!$C$24:$C$150,MATCH('1'!$B24,ROSTER!$B$24:$B$150,0),1),"") | D24: =IFERROR(INDEX(ROSTER!$AK$23:$AK$150,MATCH('1'!$B24,ROSTER!$B$23:$B$150,0),1),"") | E24: =IFERROR(INDEX(ROSTER!$AL$23:$AL$150,MATCH('1'!$B24,ROSTER!$B$23:$B$150,0),1),"") | H24: =IF(I24="","",ROW(A4)) -> 4 | I24: {=IFERROR(INDEX(ROSTER!$B$24:$B$150,MATCH(1,INDEX(($I$20=ROSTER!D$24:D$150)*(COUNTIFS(I$7:I23,ROSTER!$B$24:$B$150)=0),0,1),0),1),"")} -> Nguyễn Quang Chính | J24: =IFERROR(INDEX(ROSTER!$C$24:$C$150,MATCH('1'!$I24,ROSTER!$B$24:$B$150,0),1),"") -> VAE01375 | K24: =IFERROR(INDEX(ROSTER!$AK$23:$AK$150,MATCH('1'!$I24,ROSTER!$B$23:$B$150,0),1),"") -> B1 787 | L24: =IFERROR(INDEX(ROSTER!$AL$23:$AL$150,MATCH('1'!$I24,ROSTER!$B$23:$B$150,0),1),"") -> 0 | M24: Leader/GSGT
A25: =IF(B25="","",ROW(A6)) | B25: {=IFERROR(INDEX(ROSTER!$B$24:$B$150,MATCH(1,INDEX(($B$19=ROSTER!D$24:D$150)*(COUNTIFS(B$7:B24,ROSTER!$B$24:$B$150)=0),0,1),0),1),"")} | C25: =IFERROR(INDEX(ROSTER!$C$24:$C$150,MATCH('1'!$B25,ROSTER!$B$24:$B$150,0),1),"") | D25: =IFERROR(INDEX(ROSTER!$AK$23:$AK$150,MATCH('1'!$B25,ROSTER!$B$23:$B$150,0),1),"") | E25: =IFERROR(INDEX(ROSTER!$AL$23:$AL$70,MATCH('1'!$B25,ROSTER!$B$23:$B$150,0),1),"") | H25: =IF(I25="","",ROW(A5)) -> 5 | I25: {=IFERROR(INDEX(ROSTER!$B$24:$B$150,MATCH(1,INDEX(($I$20=ROSTER!D$24:D$150)*(COUNTIFS(I$7:I24,ROSTER!$B$24:$B$150)=0),0,1),0),1),"")} -> Huỳnh Quang Tú | J25: =IFERROR(INDEX(ROSTER!$C$24:$C$150,MATCH('1'!$I25,ROSTER!$B$24:$B$150,0),1),"") -> VAE04022 | K25: =IFERROR(INDEX(ROSTER!$AK$23:$AK$150,MATCH('1'!$I25,ROSTER!$B$23:$B$150,0),1),"") -> 0 | L25: =IFERROR(INDEX(ROSTER!$AL$23:$AL$150,MATCH('1'!$I25,ROSTER!$B$23:$B$150,0),1),"") -> 0 | M25: Tool TS5/LOCAL
A26: =IF(B26="","",ROW(A7)) | B26: {=IFERROR(INDEX(ROSTER!$B$24:$B$150,MATCH(1,INDEX(($B$19=ROSTER!D$24:D$150)*(COUNTIFS(B$7:B25,ROSTER!$B$24:$B$150)=0),0,1),0),1),"")} | C26: =IFERROR(INDEX(ROSTER!$C$24:$C$150,MATCH('1'!$B26,ROSTER!$B$24:$B$150,0),1),"") | D26: =IFERROR(INDEX(ROSTER!$AK$23:$AK$150,MATCH('1'!$B26,ROSTER!$B$23:$B$150,0),1),"") | E26: =IFERROR(INDEX(ROSTER!$AL$23:$AL$150,MATCH('1'!$B26,ROSTER!$B$23:$B$150,0),1),"") | H26: =IF(I26="","",ROW(A6)) -> 6 | I26: {=IFERROR(INDEX(ROSTER!$B$24:$B$150,MATCH(1,INDEX(($I$20=ROSTER!D$24:D$150)*(COUNTIFS(I$7:I25,ROSTER!$B$24:$B$150)=0),0,1),0),1),"")} -> Nguyễn Ngọc Trường Sơn | J26: =IFERROR(INDEX(ROSTER!$C$24:$C$150,MATCH('1'!$I26,ROSTER!$B$24:$B$150,0),1),"") -> VAE04205 | K26: =IFERROR(INDEX(ROSTER!$AK$23:$AK$150,MATCH('1'!$I26,ROSTER!$B$23:$B$150,0),1),"") -> 0 | L26: =IFERROR(INDEX(ROSTER!$AL$23:$AL$150,MATCH('1'!$I26,ROSTER!$B$23:$B$150,0),1),"") -> 0 | M26: Trực VS
A27: =IF(B27="","",ROW(A8)) | B27: {=IFERROR(INDEX(ROSTER!$B$24:$B$150,MATCH(1,INDEX(($B$19=ROSTER!D$24:D$150)*(COUNTIFS(B$7:B26,ROSTER!$B$24:$B$150)=0),0,1),0),1),"")} | C27: =IFERROR(INDEX(ROSTER!$C$24:$C$150,MATCH('1'!$B27,ROSTER!$B$24:$B$150,0),1),"") | D27: =IFERROR(INDEX(ROSTER!$AK$23:$AK$150,MATCH('1'!$B27,ROSTER!$B$23:$B$150,0),1),"") | E27: =IFERROR(INDEX(ROSTER!$AL$23:$AL$70,MATCH('1'!$B27,ROSTER!$B$23:$B$150,0),1),"") | H27: =IF(I27="","",ROW(A7)) -> 7 | I27: {=IFERROR(INDEX(ROSTER!$B$24:$B$150,MATCH(1,INDEX(($I$20=ROSTER!D$24:D$150)*(COUNTIFS(I$7:I26,ROSTER!$B$24:$B$150)=0),0,1),0),1),"")} -> Nguyễn Trí Nhân | J27: =IFERROR(INDEX(ROSTER!$C$24:$C$150,MATCH('1'!$I27,ROSTER!$B$24:$B$150,0),1),"") -> VAE03589 | K27: =IFERROR(INDEX(ROSTER!$AK$23:$AK$150,MATCH('1'!$I27,ROSTER!$B$23:$B$150,0),1),"") -> 0 | L27: =IFERROR(INDEX(ROSTER!$AL$23:$AL$150,MATCH('1'!$I27,ROSTER!$B$23:$B$150,0),1),"") -> 0 | M27: Trực VS
